Workbook

Sheet 板块数量
A1: 编号 | B1: 层号 | C1: 从上到下分格 | D1: 左立柱 | E1: 右立柱 | F1: 玻璃1 | G1: 玻璃2 | H1: 玻璃3 | I1: 高度 | J1: 宽度 | K1: 套芯 | L1: 其它 | M1: BL1 | N1: BL2 | O1: BL3 | P1: 短编号 | Q1: 数量
A2: M07-01-3-1 | B2: L11-01 | C2: 18501950 | D2: CW154H-105 | E2: CW154H-105 | F2: GL-02a-SP | G2: GL-01a | H2: - | I2: 3800 | J2: C2222 | K2: H100x50x8,H100x50x8 | L2: - | M2: BL1 | N2: BL2 | O2: BL3 | P2: D103 | Q2: 1 | S2: M18
A3: M09-05-1-1 | B3: L11-02 | C3: 18501950 | D3: CW154H-106 | E3: CW154H-103 | F3: GL-02a-SP | G3: GL-01a | H3: - | I3: 3800 | J3: 1483 | K3: -,2-62x15 | L3: 右装饰条1 | M3: BL1 | N3: BL2 | O3: BL3 | P3: D129 | Q3: 1 | S3: M23
A4: M01-01-6-1 | B4: L11-03 | C4: 18501950 | D4: CW154H-102 | E4: CW154H-101 | F4: GL-02-SP | G4: GL-01 | H4: - | I4: 3800 | J4: 1483 | K4: - | L4: - | M4: BL1 | N4: BL2 | O4: BL3 | P4: D006 | Q4: 1 | S4: M4
A5: M01-01-6-1 | B5: L11-04 | C5: 18501950 | D5: CW154H-102 | E5: CW154H-101 | F5: GL-02-SP | G5: GL-01 | H5: - | I5: 3800 | J5: 1483 | K5: - | L5: - | M5: BL1 | N5: BL2 | O5: BL3 | P5: D006 | Q5: 1 | S5: M4
A6: M01-01-6-1 | B6: L11-05 | C6: 18501950 | D6: CW154H-102 | E6: CW154H-101 | F6: GL-02-SP | G6: GL-01 | H6: - | I6: 3800 | J6: 1483 | K6: - | L6: - | M6: BL1 | N6: BL2 | O6: BL3 | P6: D006 | Q6: 1 | S6: M4
A7: M01-03-4-1 | B7: L11-06 | C7: 18501950 | D7: CW154H-102 | E7: CW154H-101 | F7: GL-02-SP | G7: GL-01 | H7: - | I7: 3800 | J7: 1483 | K7: - | L7: 右装饰条1 | M7: BL1 | N7: BL2 | O7: BL3 | P7: D015 | Q7: 1 | S7: M9
A8: M01-01-6-1 | B8: L11-07 | C8: 18501950 | D8: CW154H-102 | E8: CW154H-101 | F8: GL-02-SP | G8: GL-01 | H8: - | I8: 3800 | J8: 1483 | K8: - | L8: - | M8: BL1 | N8: BL2 | O8: BL3 | P8: D006 | Q8: 1 | S8: M4
A9: M01-01-6-1 | B9: L11-08 | C9: 18501950 | D9: CW154H-102 | E9: CW154H-101 | F9: GL-02-SP | G9: GL-01 | H9: - | I9: 3800 | J9: 1483 | K9: - | L9: - | M9: BL1 | N9: BL2 | O9: BL3 | P9: D006 | Q9: 1 | S9: M4
A10: M01-01-6-1 | B10: L11-09 | C10: 18501950 | D10: CW154H-102 | E10: CW154H-101 | F10: GL-02-SP | G10: GL-01 | H10: - | I10: 3800 | J10: 1483 | K10: - | L10: - | M10: BL1 | N10: BL2 | O10: BL3 | P10: D006 | Q10: 1 | S10: M4
A11: M01-01-6-1 | B11: L11-10 | C11: 18501950 | D11: CW154H-102 | E11: CW154H-101 | F11: GL-02-SP | G11: GL-01 | H11: - | I11: 3800 | J11: 1483 | K11: - | L11: - | M11: BL1 | N11: BL2 | O11: BL3 | P11: D006 | Q11: 1 | S11: M4
A12: M01-01-6-1 | B12: L11-11 | C12: 18501950 | D12: CW154H-102 | E12: CW154H-101 | F12: GL-02-SP | G12: GL-01 | H12: - | I12: 3800 | J12: 1483 | K12: - | L12: - | M12: BL1 | N12: BL2 | O12: BL3 | P12: D006 | Q12: 1 | S12: M4
A13: M01-01-6-1 | B13: L11-12 | C13: 18501950 | D13: CW154H-102 | E13: CW154H-101 | F13: GL-02-SP | G13: GL-01 | H13: - | I13: 3800 | J13: 1483 | K13: - | L13: - | M13: BL1 | N13: BL2 | O13: BL3 | P13: D006 | Q13: 1 | S13: M4
A14: M01-01-6-1 | B14: L11-13 | C14: 18501950 | D14: CW154H-102 | E14: CW154H-101 | F14: GL-02-SP | G14: GL-01 | H14: - | I14: 3800 | J14: 1483 | K14: - | L14: - | M14: BL1 | N14: BL2 | O14: BL3 | P14: D006 | Q14: 1 | S14: M4
... A30: M02-01-4-1 | B30: L11-29 | C30: 18501950 | D30: CW154H-102 | E30: CW154H-106 | F30: GL-02-SP | G30: GL-01 | H30: - | I30: 3800 | J30: 1483 | K30: - | L30: - | M30: BL1 | N30: BL2 | O30: BL3 | P30: D072 | Q30: 1 | S30: M14
A31: M07-01-3-1 | B31: L11-30 | C31: 18501950 | D31: CW154H-105 | E31: CW154H-105 | F31: GL-02a-SP | G31: GL-01a | H31: - | I31: 3800 | J31: C2222 | K31: H100x50x8,H100x50x8 | L31: - | M31: BL1 | N31: BL2 | O31: BL3 | P31: D103 | Q31: 1 | S31: M18
A32: M08-01-2-1 | B32: L11-31 | C32: 18501950 | D32: CW154H-106 | E32: CW154H-101 | F32: GL-02-SP | G32: GL-01 | H32: - | I32: 3800 | J32: 1461.5 | K32: - | L32: - | M32: BL1 | N32: BL2 | O32: BL3 | P32: D109 | Q32: 1 | S32: M20
A33: M01-03-3-1 | B33: L11-32 | C33: 18501950 | D33: CW154H-102 | E33: CW154H-101 | F33: GL-02-SP | G33: GL-01 | H33: - | I33: 3800 | J33: 1461.5 | K33: - | L33: 右装饰条1 | M33: BL1 | N33: BL2 | O33: BL3 | P33: D014 | Q33: 1 | S33: M8
A34: M01-01-5-1 | B34: L11-33 | C34: 18501950 | D34: CW154H-102 | E34: CW154H-101 | F34: GL-02-SP | G34: GL-01 | H34: - | I34: 3800 | J34: 1461.5 | K34: - | L34: - | M34: BL1 | N34: BL2 | O34: BL3 | P34: D005 | Q34: 1 | S34: M3
A35: M01-01-5-1 | B35: L11-34 | C35: 18501950 | D35: CW154H-102 | E35: CW154H-101 | F35: GL-02-SP | G35: GL-01 | H35: - | I35: 3800 | J35: 1461.5 | K35: - | L35: - | M35: BL1 | N35: BL2 | O35: BL3 | P35: D005 | Q35: 1 | S35: M3
A36: M01-01-5-1 | B36: L11-35 | C36: 18501950 | D36: CW154H-102 | E36: CW154H-101 | F36: GL-02-SP | G36: GL-01 | H36: - | I36: 3800 | J36: 1461.5 | K36: - | L36: - | M36: BL1 | N36: BL2 | O36: BL3 | P36: D005 | Q36: 1 | S36: M3
A37: M01-03-3-1 | B37: L11-36 | C37: 18501950 | D37: CW154H-102 | E37: CW154H-101 | F37: GL-02-SP | G37: GL-01 | H37: - | I37: 3800 | J37: 1461.5 | K37: - | L37: 右装饰条1 | M37: BL1 | N37: BL2 | O37: BL3 | P37: D014 | Q37: 1 | S37: M8
A38: M03-01-2-1 | B38: L11-37 | C38: 18501950 | D38: CW154H-102 | E38: CW154H-107 | F38: GL-02-SP | G38: GL-01 | H38: - | I38: 3800 | J38: 1461.5 | K38: - | L38: - | M38: BL1 | N38: BL2 | O38: BL3 | P38: D078 | Q38: 1 | S38: M16
A39: M10-01-3-1 | B39: L11-38 | C39: 18501950 | D39: CW154H-107 | E39: CW154H-109 | F39: AL07 | G39: AL07 | H39: - | I39: 3800 | J39: 745 | K39: - | L39: - | M39: BL1 | N39: BL2 | O39: BL3 | P39: D133 | Q39: 1
A40: M11-01-1-1 | B40: L11-39 | C40: 18501950 | D40: CW154H-109 | E40: CW154H-101 | F40: GL-02-SP | G40: GL-01 | H40: - | I40: 3800 | J40: 1438 | K40: - | L40: - | M40: BL1 | N40: BL2 | O40: BL3 | P40: D134 | Q40: 1 | S40: M24
A41: M01-01-3-1 | B41: L11-40 | C41: 18501950 | D41: CW154H-102 | E41: CW154H-101 | F41: GL-02-SP | G41: GL-01 | H41: - | I41: 3800 | J41: 1438 | K41: - | L41: - | M41: BL1 | N41: BL2 | O41: BL3 | P41: D003 | Q41: 1 | S41: M1
A42: M01-01-3-1 | B42: L11-41 | C42: 18501950 | D42: CW154H-102 | E42: CW154H-101 | F42: GL-02-SP | G42: GL-01 | H42: - | I42: 3800 | J42: 1438 | K42: - | L42: - | M42: BL1 | N42: BL2 | O42: BL3 | P42: D003 | Q42: 1 | S42: M1
A43: M01-01-3-1 | B43: L11-42 | C43: 18501950 | D43: CW154H-102 | E43: CW154H-101 | F43: GL-02-SP | G43: GL-01 | H43: - | I43: 3800 | J43: 1438 | K43: - | L43: - | M43: BL1 | N43: BL2 | O43: BL3 | P43: D003 | Q43: 1 | S43: M1
A44: M01-03-1-1 | B44: L11-43 | C44: 18501950 | D44: CW154H-102 | E44: CW154H-101 | F44: GL-02-SP | G44: GL-01 | H44: - | I44: 3800 | J44: 1438 | K44: - | L44: 右装饰条1 | M44: BL1 | N44: BL2 | O44: BL3 | P44: D012 | Q44: 1 | S44: M6
A45: M01-01-3-1 | B45: L11-44 | C45: 18501950 | D45: CW154H-102 | E45: CW154H-101 | F45: GL-02-SP | G45: GL-01 | H45: - | I45: 3800 | J45: 1438 | K45: - | L45: - | M45: BL1 | N45: BL2 | O45: BL3 | P45: D003 | Q45: 1 | S45: M1
A46: M01-01-3-1 | B46: L11-45 | C46: 18501950 | D46: CW154H-102 | E46: CW154H-101 | F46: GL-02-SP | G46: GL-01 | H46: - | I46: 3800 | J46: 1438 | K46: - | L46: - | M46: BL1 | N46: BL2 | O46: BL3 | P46: D003 | Q46: 1 | S46: M1
A47: M01-01-3-1 | B47: L11-46 | C47: 18501950 | D47: CW154H-102 | E47: CW154H-101 | F47: GL-02-SP | G47: GL-01 | H47: - | I47: 3800 | J47: 1438 | K47: - | L47: - | M47: BL1 | N47: BL2 | O47: BL3 | P47: D003 | Q47: 1 | S47: M1
A48: M01-01-3-1 | B48: L11-47 | C48: 18501950 | D48: CW154H-102 | E48: CW154H-101 | F48: GL-02-SP | G48: GL-01 | H48: - | I48: 3800 | J48: 1438 | K48: - | L48: - | M48: BL1 | N48: BL2 | O48: BL3 | P48: D003 | Q48: 1 | S48: M1
A49: M01-03-1-1 | B49: L11-48 | C49: 18501950 | D49: CW154H-102 | E49: CW154H-101 | F49: GL-02-SP | G49: GL-01 | H49: - | I49: 3800 | J49: 1438 | K49: - | L49: 右装饰条1 | M49: BL1 | N49: BL2 | O49: BL3 | P49: D012 | Q49: 1 | S49: M6
A50: M02-01-3-1 | B50: L11-49 | C50: 18501950 | D50: CW154H-102 | E50: CW154H-106 | F50: GL-02-SP | G50: GL-01 | H50: - | I50: 3800 | J50: 1438 | K50: - | L50: - | M50: BL1 | N50: BL2 | O50: BL3 | P50: D071 | Q50: 1 | S50: M13
A51: M07-01-3-2 | B51: L11-50 | C51: 18501950 | D51: CW154H-105 | E51: CW154H-105 | F51: GL-02a-SP | G51: GL-01a | H51: - | I51: 3800 | J51: C2222 | K51: H100x50x8,H100x50x8 | L51: - | M51: BL1 | N51: BL2 | O51: BL3 | P51: D103 | Q51: 1 | S51: M19
A52: M08-01-4-1 | B52: L11-51 | C52: 18501950 | D52: CW154H-106 | E52: CW154H-101 | F52: GL-02-SP | G52: GL-01 | H52: - | I52: 3800 | J52: 1494 | K52: - | L52: - | M52: BL1 | N52: BL2 | O52: BL3 | P52: D111 | Q52: 1 | S52: M21
A53: M01-01-7-1 | B53: L11-52 | C53: 18501950 | D53: CW154H-102 | E53: CW154H-101 | F53: GL-02-SP | G53: GL-01 | H53: - | I53: 3800 | J53: 1494 | K53: - | L53: - | M53: BL1 | N53: BL2 | O53: BL3 | P53: D007 | Q53: 1 | S53: M5
A54: M01-03-5-1 | B54: L11-53 | C54: 18501950 | D54: CW154H-102 | E54: CW154H-101 | F54: GL-02-SP | G54: GL-01 | H54: - | I54: 3800 | J54: 1494 | K54: - | L54: 右装饰条1 | M54: BL1 | N54: BL2 | O54: BL3 | P54: D016 | Q54: 1 | S54: M10
A55: M01-01-7-1 | B55: L11-54 | C55: 18501950 | D55: CW154H-102 | E55: CW154H-101 | F55: GL-02-SP | G55: GL-01 | H55: - | I55: 3800 | J55: 1494 | K55: - | L55: - | M55: BL1 | N55: BL2 | O55: BL3 | P55: D007 | Q55: 1 | S55: M5
...

Sheet M01-01-3-1
W2: 函数区，请勿编辑
F4: 项目名称： | H4: DARWIN CIVIC CENTRE | J4: 单元体加工单 | O4: 分格尺寸： | P4: 3800 | Q4: * | R4: 1438
F5: 工程编号： | H5: SYE-HK-25C004 | J5: 加工单编号： | K5: M01-01-3-1 | M5: 版 本： | N5: V0 | O5: 板块尺寸： | P5: 3830 | Q5: * | R5: 1459.5 | S5: * | T5: 262.5
F6: 板块名称： | H6: 见"板块名称"列 | J6: 加工部位： | K6: 11F | M6: 加工总数： | N6: =SUMPRODUCT(--(R9:R73<>"")) -> 7 | O6: 樘
B7: 函数区，请勿编辑 | F7: 装配图号： | H7: M01-01-3-1 | J7: 设 计： | K7: 彭玲 | M7: 核 对： | N7: 张小明 | P7: 批准： | Q7: 刘维 | W7: 铝材优化 | AE7: 铝材清单 | AP7: 配件清单 | AY7: 玻璃清单 | BI7: 铝板清单 | BS7: 镀锌铁皮清单 | CC7: 铁件清单
E8: 序号 | F8: 序号 | G8: 类型 | H8: 零件名称 | I8: 模号/型号 | J8: 零件编号 | K8: 加工图编号 | L8: 长度/H | M8: 宽度/W | N8: 厚度/t | O8: 数量/樘 | P8: 单位 | Q8: 板块名称 | W8: 型材名称 | X8: 厂家模号 | Y8: 长度 | Z8: 图纸编号 | AA8: 数量 | AB8: 颜色 | AC8: 类型 | AE8: 材料编号 | AF8: 铝材名称 | AG8: 厂家模号 | AH8: 颜色/表面处理（代码） | AI8: 长度 | AJ8: 线密度（kg/m） | AK8: 数量(支) | AL8: 重量 | AM8: 颜色/表面处理（具体色号） | AN8: 备 注 | AP8: 编号/规格型号 | AQ8: 配件名称 | AR8: 类型/材料/表面处理 | AS8: 数量 | AT8: 单位 | AU8: 订料编号 | AV8: 回料情况 | AW8: 供应商/备注 | AY8: 单元板编号 | AZ8: 玻璃编号 | BA8: 玻璃配置描述 | BB8: 宽 | BC8: 高 | BD8: 数量 | BE8: 面积 | BF8: 图纸编号 | BG8: 备注 | BI8: 单元板编号 | BJ8: 板材编号 | BK8: 板材名称 | BL8: 宽 | BM8: 高 | BN8: 数量 | BO8: 面积 | BP8: 图纸编号 | BQ8: 备注 | BS8: 单元板编号 | BT8: 板材编号 | BU8: 板材名称 | BV8: 宽 | BW8: 高 | BX8: 数量 | BY8: 面积 | BZ8: 图纸编号 | CA8: 备注 | CC8: 单元板编号 | CD8: 铁件编号 | CE8: 铁件名称 | CF8: 长(mm) | CG8: 米重kg/m | CH8: 数量 | CI8: 表面处理 | CJ8: 图纸编号 | CK8: 备注
B9: =IF(G9<>G8,B8+1,B8) -> 1 | C9: =IF(G9<>G8,1,C8+1) -> 1 | D9: =IF(G9="","",IFERROR(IF(AND(B9<>"",C9<>""),B9&"."&C9,""),"")) | E9: 1 | F9: 主材 | R9: {=IFERROR(INDEX(板块数量!$B$2:$B$118,MATCH(0,IF((板块数量!$A$2:$A$118=$K$5)*(板块数量!$B$2:$B$118<>""),COUNTIF($R$8:R8,板块数量!$B$2:$B$118),1),0)),"")} -> L11-40 | W9: =IF(OR($G9="型材",$G9="尼龙"),H9,"-") -> - | X9: =IF(OR($G9="型材",$G9="尼龙"),I9,"-") -> - | Y9: =IF(OR($G9="型材",$G9="尼龙"),L9,"-") -> - | Z9: =IF(OR(G9="型材",G9="尼龙"),K9,"-") -> - | AA9: =IF(OR($G9="型材",$G9="尼龙"),$N$6*O9,"-") -> - | AF9: =IF(OR(G9="型材",G9="尼龙"),H9,"-") -> - | AG9: =IF(OR(G9="型材",G9="尼龙"),I9,"-") -> - | AI9: =IF(OR(G9="型材",G9="尼龙"),L9,"-") -> - | AK9: =IF(OR(G9="型材",G9="尼龙"),$N$6*O9,"-") -> - | AP9: =IF($G9="配件",I9,"-") -> - | AQ9: =IF($G9="配件",H9,"-") -> - | AS9: =IF(OR(H9="泡沫条",H9="胶条"),$N$6*L9*O9/1000,IF(OR(H9="双面贴",H9="胶带"),L9*O9/1000,IF(AP9<>"-",$N$6*O9,"-"))) -> - | AT9: =IF(OR(H9="胶条",H9="泡沫条",H9="双面贴",H9="胶带"),"米",IF(AP9<>"-",P9,"-")) -> - | AY9: =IF($G9="玻璃",$H$7,"-") -> - | AZ9: =IF($G9="玻璃",J9,"-") -> - | BB9: =IF($G9="玻璃",M9,"-") -> - | BC9: =IF($G9="玻璃",L9,"-") -> - | BD9: =IF($G9="玻璃",$N$6*O9,"-") -> - | BE9: =BD9*BC9*BB9/1000000 -> #VALUE! | BF9: =IF($G9="玻璃",K9,"-") -> - | BI9: =IF($G9="铝板",$H$7,"-") -> - | BJ9: =IF($G9="铝板",J9,"-") -> - | BK9: =IF($G9="铝板",H9,"-") -> - | BL9: =IF($G9="铝板",M9,"-") -> - | BM9: =IF($G9="铝板",L9,"-") -> - | BN9: =IF($G9="铝板",$N$6*O9,"-") -> - | BO9: =BN9*BM9*BL9/1000000 -> #VALUE! | BP9: =IF($G9="铝板",K9,"-") -> - | BS9: =IF($G9="铁皮",$H$7,"-") -> - | BT9: =IF($G9="铁皮",J9,"-") -> - | BU9: =IF($G9="铁皮",H9,"-") -> - | BV9: =IF($G9="铁皮",M9,"-") -> - | BW9: =IF($G9="铁皮",L9,"-") -> - | BX9: =IF($G9="铁皮",$N$6*O9,"-") -> - | BY9: =BX9*BW9*BV9/1000000 -> #VALUE! | BZ9: =IF($G9="铁皮",K9,"-") -> - | CC9: =IF(G9="钢材",$H$7,"-") -> - | CD9: =IF(G9="钢材",J9,"-") -> - | CE9: =IF(G9="钢材",H9,"-") -> - | CF9: =IF(G9="钢材",L9,"-") -> - | CH9: =IF(G9="钢材",$N$6*O9,"-") -> - | CJ9: =IF(G9="钢材",K9,"-") -> - | CK9: =IF(G9="钢材",Q9,"-") -> -
B10: =IF(G10<>G9,B9+1,B9) -> 2 | C10: =IF(G10<>G9,1,C9+1) -> 1 | D10: =IF(G10="","",IFERROR(IF(AND(B10<>"",C10<>""),B10&"."&C10,""),"")) -> 2.1 | E10: 2 | F10: 1 | G10: 铁皮 | H10: 1.2mm镀锌铁皮 | I10: DX51D+Z-70 | J10: 板块名-SP01 | K10: - | L10: 1729 | M10: 1334 | N10: 1 | O10: 1 | P10: 块 | R10: {=IFERROR(INDEX(板块数量!$B$2:$B$118,MATCH(0,IF((板块数量!$A$2:$A$118=$K$5)*(板块数量!$B$2:$B$118<>""),COUNTIF($R$8:R9,板块数量!$B$2:$B$118),1),0)),"")} -> L11-41 | W10: =IF(OR(G10="型材",G10="尼龙"),H10,"-") -> - | X10: =IF(OR(G10="型材",G10="尼龙"),I10,"-") -> - | Y10: =IF(OR(G10="型材",G10="尼龙"),L10,"-") -> - | Z10: =IF(OR(G10="型材",G10="尼龙"),K10,"-") -> - | AA10: =IF(OR(G10="型材",G10="尼龙"),$N$6*O10,"-") -> - | AF10: =IF(OR(G10="型材",G10="尼龙"),H10,"-") -> - | AG10: =IF(OR(G10="型材",G10="尼龙"),I10,"-") -> - | AI10: =IF(OR(G10="型材",G10="尼龙"),L10,"-") -> - | AK10: =IF(OR(G10="型材",G10="尼龙"),$N$6*O10,"-") -> - | AP10: =IF($G10="配件",I10,"-") -> - | AQ10: =IF($G10="配件",H10,"-") -> - | AS10: =IF(OR(H10="泡沫条",H10="胶条"),$N$6*L10*O10/1000,IF(OR(H10="双面贴",H10="胶带"),L10*O10/1000,IF(AP10<>"-",$N$6*O10,"-"))) -> - | AT10: =IF(OR(H10="胶条",H10="泡沫条",H10="双面贴",H10="胶带"),"米",IF(AP10<>"-",P10,"-")) -> - | AY10: =IF($G10="玻璃",$H$7,"-") -> - | AZ10: =IF($G10="玻璃",J10,"-") -> - | BB10: =IF($G10="玻璃",M10,"-") -> - | BC10: =IF($G10="玻璃",L10,"-") -> - | BD10: =IF($G10="玻璃",$N$6*O10,"-") -> - | BE10: =BD10*BC10*BB10/1000000 -> #VALUE! | BF10: =IF($G10="玻璃",K10,"-") -> - | BI10: =IF($G10="铝板",$H$7,"-") -> - | BJ10: =IF($G10="铝板",J10,"-") -> - | BK10: =IF($G10="铝板",H10,"-") -> - | BL10: =IF($G10="铝板",M10,"-") -> - | BM10: =IF($G10="铝板",L10,"-") -> - | BN10: =IF($G10="铝板",$N$6*O10,"-") -> - | BO10: =BN10*BM10*BL10/1000000 -> #VALUE! | BP10: =IF($G10="铝板",K10,"-") -> - | BS10: =IF($G10="铁皮",$H$7,"-") -> M01-01-3-1 | BT10: =IF($G10="铁皮",J10,"-") -> 板块名-SP01 | BU10: =IF($G10="铁皮",H10,"-") -> 1.2mm镀锌铁皮 | BV10: =IF($G10="铁皮",M10,"-") -> 1334 | BW10: =IF($G10="铁皮",L10,"-") -> 1729 | BX10: =IF($G10="铁皮",$N$6*O10,"-") -> 7 | BY10: =BX10*BW10*BV10/1000000 -> 16.145402 | BZ10: =IF($G10="铁皮",K10,"-") -> - | CC10: =IF(G10="钢材",$H$7,"-") -> - | CD10: =IF(G10="钢材",J10,"-") -> - | CE10: =IF(G10="钢材",H10,"-") -> - | CF10: =IF(G10="钢材",L10,"-") -> - | CH10: =IF(G10="钢材",$N$6*O10,"-") -> - | CJ10: =IF(G10="钢材",K10,"-") -> - | CK10: =IF(G10="钢材",Q10,"-") -> -
B11: =IF(G11<>G10,B10+1,B10) -> 3 | C11: =IF(G11<>G10,1,C10+1) -> 1 | D11: =IF(G11="","",IFERROR(IF(AND(B11<>"",C11<>""),B11&"."&C11,""),"")) -> 3.1 | E11: 3 | F11: 2 | G11: 玻璃 | H11: GL02 | I11: GL02 | J11: 板块名-GL02-01 | K11: - | L11: 1808 | M11: 1402 | N11: 24 | O11: 1 | P11: 块 | R11: {=IFERROR(INDEX(板块数量!$B$2:$B$118,MATCH(0,IF((板块数量!$A$2:$A$118=$K$5)*(板块数量!$B$2:$B$118<>""),COUNTIF($R$8:R10,板块数量!$B$2:$B$118),1),0)),"")} -> L11-42 | W11: =IF(OR(G11="型材",G11="尼龙"),H11,"-") -> - | X11: =IF(OR(G11="型材",G11="尼龙"),I11,"-") -> - | Y11: =IF(OR(G11="型材",G11="尼龙"),L11,"-") -> - | Z11: =IF(OR(G11="型材",G11="尼龙"),K11,"-") -> - | AA11: =IF(OR(G11="型材",G11="尼龙"),$N$6*O11,"-") -> - | AF11: =IF(OR(G11="型材",G11="尼龙"),H11,"-") -> - | AG11: =IF(OR(G11="型材",G11="尼龙"),I11,"-") -> - | AI11: =IF(OR(G11="型材",G11="尼龙"),L11,"-") -> - | AK11: =IF(OR(G11="型材",G11="尼龙"),$N$6*O11,"-") -> - | AP11: =IF($G11="配件",I11,"-") -> - | AQ11: =IF($G11="配件",H11,"-") -> - | AS11: =IF(OR(H11="泡沫条",H11="胶条"),$N$6*L11*O11/1000,IF(OR(H11="双面贴",H11="胶带"),L11*O11/1000,IF(AP11<>"-",$N$6*O11,"-"))) -> - | AT11: =IF(OR(H11="胶条",H11="泡沫条",H11="双面贴",H11="胶带"),"米",IF(AP11<>"-",P11,"-")) -> - | AY11: =IF($G11="玻璃",$H$7,"-") -> M01-01-3-1 | AZ11: =IF($G11="玻璃",J11,"-") -> 板块名-GL02-01 | BB11: =IF($G11="玻璃",M11,"-") -> 1402 | BC11: =IF($G11="玻璃",L11,"-") -> 1808 | BD11: =IF($G11="玻璃",$N$6*O11,"-") -> 7 | BE11: =BD11*BC11*BB11/1000000 -> 17.743712 | BF11: =IF($G11="玻璃",K11,"-") -> - | BI11: =IF($G11="铝板",$H$7,"-") -> - | BJ11: =IF($G11="铝板",J11,"-") -> - | BK11: =IF($G11="铝板",H11,"-") -> - | BL11: =IF($G11="铝板",M11,"-") -> - | BM11: =IF($G11="铝板",L11,"-") -> - | BN11: =IF($G11="铝板",$N$6*O11,"-") -> - | BO11: =BN11*BM11*BL11/1000000 -> #VALUE! | BP11: =IF($G11="铝板",K11,"-") -> - | BS11: =IF($G11="铁皮",$H$7,"-") -> - | BT11: =IF($G11="铁皮",J11,"-") -> - | BU11: =IF($G11="铁皮",H11,"-") -> - | BV11: =IF($G11="铁皮",M11,"-") -> - | BW11: =IF($G11="铁皮",L11,"-") -> - | BX11: =IF($G11="铁皮",$N$6*O11,"-") -> - | BY11: =BX11*BW11*BV11/1000000 -> #VALUE! | BZ11: =IF($G11="铁皮",K11,"-") -> - | CC11: =IF(G11="钢材",$H$7,"-") -> - | CD11: =IF(G11="钢材",J11,"-") -> - | CE11: =IF(G11="钢材",H11,"-") -> - | CF11: =IF(G11="钢材",L11,"-") -> - | CH11: =IF(G11="钢材",$N$6*O11,"-") -> - | CJ11: =IF(G11="钢材",K11,"-") -> - | CK11: =IF(G11="钢材",Q11,"-") -> -
B12: =IF(G12<>G11,B11+1,B11) -> 3 | C12: =IF(G12<>G11,1,C11+1) -> 2 | D12: =IF(G12="","",IFERROR(IF(AND(B12<>"",C12<>""),B12&"."&C12,""),"")) -> 3.2 | E12: 4 | F12: 3 | G12: 玻璃 | H12: GL01 | I12: GL01 | J12: 板块名-GL01-01 | K12: - | L12: 1907 | M12: 1402 | N12: 24 | O12: 1 | P12: 块 | R12: {=IFERROR(INDEX(板块数量!$B$2:$B$118,MATCH(0,IF((板块数量!$A$2:$A$118=$K$5)*(板块数量!$B$2:$B$118<>""),COUNTIF($R$8:R11,板块数量!$B$2:$B$118),1),0)),"")} -> L11-44 | W12: =IF(OR(G12="型材",G12="尼龙"),H12,"-") -> - | X12: =IF(OR(G12="型材",G12="尼龙"),I12,"-") -> - | Y12: =IF(OR(G12="型材",G12="尼龙"),L12,"-") -> - | Z12: =IF(OR(G12="型材",G12="尼龙"),K12,"-") -> - | AA12: =IF(OR(G12="型材",G12="尼龙"),$N$6*O12,"-") -> - | AF12: =IF(OR(G12="型材",G12="尼龙"),H12,"-") -> - | AG12: =IF(OR(G12="型材",G12="尼龙"),I12,"-") -> - | AI12: =IF(OR(G12="型材",G12="尼龙"),L12,"-") -> - | AK12: =IF(OR(G12="型材",G12="尼龙"),$N$6*O12,"-") -> - | AP12: =IF($G12="配件",I12,"-") -> - | AQ12: =IF($G12="配件",H12,"-") -> - | AS12: =IF(OR(H12="泡沫条",H12="胶条"),$N$6*L12*O12/1000,IF(OR(H12="双面贴",H12="胶带"),L12*O12/1000,IF(AP12<>"-",$N$6*O12,"-"))) -> - | AT12: =IF(OR(H12="胶条",H12="泡沫条",H12="双面贴",H12="胶带"),"米",IF(AP12<>"-",P12,"-")) -> - | AY12: =IF($G12="玻璃",$H$7,"-") -> M01-01-3-1 | AZ12: =IF($G12="玻璃",J12,"-") -> 板块名-GL01-01 | BB12: =IF($G12="玻璃",M12,"-") -> 1402 | BC12: =IF($G12="玻璃",L12,"-") -> 1907 | BD12: =IF($G12="玻璃",$N$6*O12,"-") -> 7 | BE12: =BD12*BC12*BB12/1000000 -> 18.715298 | BF12: =IF($G12="玻璃",K12,"-") -> - | BI12: =IF($G12="铝板",$H$7,"-") -> - | BJ12: =IF($G12="铝板",J12,"-") -> - | BK12: =IF($G12="铝板",H12,"-") -> - | BL12: =IF($G12="铝板",M12,"-") -> - | BM12: =IF($G12="铝板",L12,"-") -> - | BN12: =IF($G12="铝板",$N$6*O12,"-") -> - | BO12: =BN12*BM12*BL12/1000000 -> #VALUE! | BP12: =IF($G12="铝板",K12,"-") -> - | BS12: =IF($G12="铁皮",$H$7,"-") -> - | BT12: =IF($G12="铁皮",J12,"-") -> - | BU12: =IF($G12="铁皮",H12,"-") -> - | BV12: =IF($G12="铁皮",M12,"-") -> - | BW12: =IF($G12="铁皮",L12,"-") -> - | BX12: =IF($G12="铁皮",$N$6*O12,"-") -> - | BY12: =BX12*BW12*BV12/1000000 -> #VALUE! | BZ12: =IF($G12="铁皮",K12,"-") -> - | CC12: =IF(G12="钢材",$H$7,"-") -> - | CD12: =IF(G12="钢材",J12,"-") -> - | CE12: =IF(G12="钢材",H12,"-") -> - | CF12: =IF(G12="钢材",L12,"-") -> - | CH12: =IF(G12="钢材",$N$6*O12,"-") -> - | CJ12: =IF(G12="钢材",K12,"-") -> - | CK12: =IF(G12="钢材",Q12,"-") -> -
B13: =IF(G13<>G12,B12+1,B12) -> 4 | C13: =IF(G13<>G12,1,C12+1) -> 1 | D13: =IF(G13="","",IFERROR(IF(AND(B13<>"",C13<>""),B13&"."&C13,""),"")) -> 4.1 | E13: 5 | F13: 4 | G13: 尼龙 | H13: 隔热条 | I13: SYE-NL08 | J13: SYE-NL08-03 | K13: SYE-NL08-03 | L13: 3760 | M13: 7.6 | N13: 33.1 | O13: 2 | P13: 支 | R13: {=IFERROR(INDEX(板块数量!$B$2:$B$118,MATCH(0,IF((板块数量!$A$2:$A$118=$K$5)*(板块数量!$B$2:$B$118<>""),COUNTIF($R$8:R12,板块数量!$B$2:$B$118),1),0)),"")} -> L11-45 | W13: =IF(OR(G13="型材",G13="尼龙"),H13,"-") -> 隔热条 | X13: =IF(OR(G13="型材",G13="尼龙"),I13,"-") -> SYE-NL08 | Y13: =IF(OR(G13="型材",G13="尼龙"),L13,"-") -> 3760 | Z13: =IF(OR(G13="型材",G13="尼龙"),K13,"-") -> SYE-NL08-03 | AA13: =IF(OR(G13="型材",G13="尼龙"),$N$6*O13,"-") -> 14 | AF13: =IF(OR(G13="型材",G13="尼龙"),H13,"-") -> 隔热条 | AG13: =IF(OR(G13="型材",G13="尼龙"),I13,"-") -> SYE-NL08 | AI13: =IF(OR(G13="型材",G13="尼龙"),L13,"-") -> 3760 | AK13: =IF(OR(G13="型材",G13="尼龙"),$N$6*O13,"-") -> 14 | AP13: =IF($G13="配件",I13,"-") -> - | AQ13: =IF($G13="配件",H13,"-") -> - | AS13: =IF(OR(H13="泡沫条",H13="胶条"),$N$6*L13*O13/1000,IF(OR(H13="双面贴",H13="胶带"),L13*O13/1000,IF(AP13<>"-",$N$6*O13,"-"))) -> - | AT13: =IF(OR(H13="胶条",H13="泡沫条",H13="双面贴",H13="胶带"),"米",IF(AP13<>"-",P13,"-")) -> - | AY13: =IF($G13="玻璃",$H$7,"-") -> - | AZ13: =IF($G13="玻璃",J13,"-") -> - | BB13: =IF($G13="玻璃",M13,"-") -> - | BC13: =IF($G13="玻璃",L13,"-") -> - | BD13: =IF($G13="玻璃",$N$6*O13,"-") -> - | BE13: =BD13*BC13*BB13/1000000 -> #VALUE! | BF13: =IF($G13="玻璃",K13,"-") -> - | BI13: =IF($G13="铝板",$H$7,"-") -> - | BJ13: =IF($G13="铝板",J13,"-") -> - | BK13: =IF($G13="铝板",H13,"-") -> - | BL13: =IF($G13="铝板",M13,"-") -> - | BM13: =IF($G13="铝板",L13,"-") -> - | BN13: =IF($G13="铝板",$N$6*O13,"-") -> - | BO13: =BN13*BM13*BL13/1000000 -> #VALUE! | BP13: =IF($G13="铝板",K13,"-") -> - | BS13: =IF($G13="铁皮",$H$7,"-") -> - | BT13: =IF($G13="铁皮",J13,"-") -> - | BU13: =IF($G13="铁皮",H13,"-") -> - | BV13: =IF($G13="铁皮",M13,"-") -> - | BW13: =IF($G13="铁皮",L13,"-") -> - | BX13: =IF($G13="铁皮",$N$6*O13,"-") -> - | BY13: =BX13*BW13*BV13/1000000 -> #VALUE! | BZ13: =IF($G13="铁皮",K13,"-") -> - | CC13: =IF(G13="钢材",$H$7,"-") -> - | CD13: =IF(G13="钢材",J13,"-") -> - | CE13: =IF(G13="钢材",H13,"-") -> - | CF13: =IF(G13="钢材",L13,"-") -> - | CH13: =IF(G13="钢材",$N$6*O13,"-") -> - | CJ13: =IF(G13="钢材",K13,"-") -> - | CK13: =IF(G13="钢材",Q13,"-") -> -
B14: =IF(G14<>G13,B13+1,B13) -> 5 | C14: =IF(G14<>G13,1,C13+1) -> 1 | D14: =IF(G14="","",IFERROR(IF(AND(B14<>"",C14<>""),B14&"."&C14,""),"")) -> 5.1 | E14: 6 | F14: 5 | G14: 型材 | H14: 转接件 | I14: DCC154H-607-LL | J14: CW154H-607-01 | K14: CW154H-607-01 | L14: 1338 | M14: 91 | N14: 6.2 | O14: 1 | P14: 支 | R14: {=IFERROR(INDEX(板块数量!$B$2:$B$118,MATCH(0,IF((板块数量!$A$2:$A$118=$K$5)*(板块数量!$B$2:$B$118<>""),COUNTIF($R$8:R13,板块数量!$B$2:$B$118),1),0)),"")} -> L11-46 | W14: =IF(OR(G14="型材",G14="尼龙"),H14,"-") -> 转接件 | X14: =IF(OR(G14="型材",G14="尼龙"),I14,"-") -> DCC154H-607-LL | Y14: =IF(OR(G14="型材",G14="尼龙"),L14,"-") -> 1338 | Z14: =IF(OR(G14="型材",G14="尼龙"),K14,"-") -> CW154H-607-01 | AA14: =IF(OR(G14="型材",G14="尼龙"),$N$6*O14,"-") -> 7 | AF14: =IF(OR(G14="型材",G14="尼龙"),H14,"-") -> 转接件 | AG14: =IF(OR(G14="型材",G14="尼龙"),I14,"-") -> DCC154H-607-LL | AI14: =IF(OR(G14="型材",G14="尼龙"),L14,"-") -> 1338 | AK14: =IF(OR(G14="型材",G14="尼龙"),$N$6*O14,"-") -> 7 | AP14: =IF($G14="配件",I14,"-") -> - | AQ14: =IF($G14="配件",H14,"-") -> - | AS14: =IF(OR(H14="泡沫条",H14="胶条"),$N$6*L14*O14/1000,IF(OR(H14="双面贴",H14="胶带"),L14*O14/1000,IF(AP14<>"-",$N$6*O14,"-"))) -> - | AT14: =IF(OR(H14="胶条",H14="泡沫条",H14="双面贴",H14="胶带"),"米",IF(AP14<>"-",P14,"-")) -> - | AY14: =IF($G14="玻璃",$H$7,"-") -> - | AZ14: =IF($G14="玻璃",J14,"-") -> - | BB14: =IF($G14="玻璃",M14,"-") -> - | BC14: =IF($G14="玻璃",L14,"-") -> - | BD14: =IF($G14="玻璃",$N$6*O14,"-") -> - | BE14: =BD14*BC14*BB14/1000000 -> #VALUE! | BF14: =IF($G14="玻璃",K14,"-") -> - | BI14: =IF($G14="铝板",$H$7,"-") -> - | BJ14: =IF($G14="铝板",J14,"-") -> - | BK14: =IF($G14="铝板",H14,"-") -> - | BL14: =IF($G14="铝板",M14,"-") -> - | BM14: =IF($G14="铝板",L14,"-") -> - | BN14: =IF($G14="铝板",$N$6*O14,"-") -> - | BO14: =BN14*BM14*BL14/1000000 -> #VALUE! | BP14: =IF($G14="铝板",K14,"-") -> - | BS14: =IF($G14="铁皮",$H$7,"-") -> - | BT14: =IF($G14="铁皮",J14,"-") -> - | BU14: =IF($G14="铁皮",H14,"-") -> - | BV14: =IF($G14="铁皮",M14,"-") -> - | BW14: =IF($G14="铁皮",L14,"-") -> - | BX14: =IF($G14="铁皮",$N$6*O14,"-") -> - | BY14: =BX14*BW14*BV14/1000000 -> #VALUE! | BZ14: =IF($G14="铁皮",K14,"-") -> - | CC14: =IF(G14="钢材",$H$7,"-") -> - | CD14: =IF(G14="钢材",J14,"-") -> - | CE14: =IF(G14="钢材",H14,"-") -> - | CF14: =IF(G14="钢材",L14,"-") -> - | CH14: =IF(G14="钢材",$N$6*O14,"-") -> - | CJ14: =IF(G14="钢材",K14,"-") -> - | CK14: =IF(G14="钢材",Q14,"-") -> -
B15: =IF(G15<>G14,B14+1,B14) -> 5 | C15: =IF(G15<>G14,1,C14+1) -> 2 | D15: =IF(G15="","",IFERROR(IF(AND(B15<>"",C15<>""),B15&"."&C15,""),"")) -> 5.2 | E15: 7 | F15: 6 | G15: 型材 | H15: 角铝 | I15: J55X20X3 | J15: J55X20X3-01 | K15: J55X20X3-01 | L15: 1298 | M15: 55 | N15: 20 | O15: 1 | P15: 支 | R15: {=IFERROR(INDEX(板块数量!$B$2:$B$118,MATCH(0,IF((板块数量!$A$2:$A$118=$K$5)*(板块数量!$B$2:$B$118<>""),COUNTIF($R$8:R14,板块数量!$B$2:$B$118),1),0)),"")} -> L11-47 | W15: =IF(OR(G15="型材",G15="尼龙"),H15,"-") -> 角铝 | X15: =IF(OR(G15="型材",G15="尼龙"),I15,"-") -> J55X20X3 | Y15: =IF(OR(G15="型材",G15="尼龙"),L15,"-") -> 1298 | Z15: =IF(OR(G15="型材",G15="尼龙"),K15,"-") -> J55X20X3-01 | AA15: =IF(OR(G15="型材",G15="尼龙"),$N$6*O15,"-") -> 7 | AF15: =IF(OR(G15="型材",G15="尼龙"),H15,"-") -> 角铝 | AG15: =IF(OR(G15="型材",G15="尼龙"),I15,"-") -> J55X20X3 | AI15: =IF(OR(G15="型材",G15="尼龙"),L15,"-") -> 1298 | AK15: =IF(OR(G15="型材",G15="尼龙"),$N$6*O15,"-") -> 7 | AP15: =IF($G15="配件",I15,"-") -> - | AQ15: =IF($G15="配件",H15,"-") -> - | AS15: =IF(OR(H15="泡沫条",H15="胶条"),$N$6*L15*O15/1000,IF(OR(H15="双面贴",H15="胶带"),L15*O15/1000,IF(AP15<>"-",$N$6*O15,"-"))) -> - | AT15: =IF(OR(H15="胶条",H15="泡沫条",H15="双面贴",H15="胶带"),"米",IF(AP15<>"-",P15,"-")) -> - | AY15: =IF($G15="玻璃",$H$7,"-") -> - | AZ15: =IF($G15="玻璃",J15,"-") -> - | BB15: =IF($G15="玻璃",M15,"-") -> - | BC15: =IF($G15="玻璃",L15,"-") -> - | BD15: =IF($G15="玻璃",$N$6*O15,"-") -> - | BE15: =BD15*BC15*BB15/1000000 -> #VALUE! | BF15: =IF($G15="玻璃",K15,"-") -> - | BI15: =IF($G15="铝板",$H$7,"-") -> - | BJ15: =IF($G15="铝板",J15,"-") -> - | BK15: =IF($G15="铝板",H15,"-") -> - | BL15: =IF($G15="铝板",M15,"-") -> - | BM15: =IF($G15="铝板",L15,"-") -> - | BN15: =IF($G15="铝板",$N$6*O15,"-") -> - | BO15: =BN15*BM15*BL15/1000000 -> #VALUE! | BP15: =IF($G15="铝板",K15,"-") -> - | BS15: =IF($G15="铁皮",$H$7,"-") -> - | BT15: =IF($G15="铁皮",J15,"-") -> - | BU15: =IF($G15="铁皮",H15,"-") -> - | BV15: =IF($G15="铁皮",M15,"-") -> - | BW15: =IF($G15="铁皮",L15,"-") -> - | BX15: =IF($G15="铁皮",$N$6*O15,"-") -> - | BY15: =BX15*BW15*BV15/1000000 -> #VALUE! | BZ15: =IF($G15="铁皮",K15,"-") -> - | CC15: =IF(G15="钢材",$H$7,"-") -> - | CD15: =IF(G15="钢材",J15,"-") -> - | CE15: =IF(G15="钢材",H15,"-") -> - | CF15: =IF(G15="钢材",L15,"-") -> - | CH15: =IF(G15="钢材",$N$6*O15,"-") -> - | CJ15: =IF(G15="钢材",K15,"-") -> - | CK15: =IF(G15="钢材",Q15,"-") -> -
B16: =IF(G16<>G15,B15+1,B15) -> 5 | C16: =IF(G16<>G15,1,C15+1) -> 3 | D16: =IF(G16="","",IFERROR(IF(AND(B16<>"",C16<>""),B16&"."&C16,""),"")) -> 5.3 | E16: 8 | F16: 7 | G16: 型材 | H16: 角铝 | I16: J25X19X3 | J16: J25X19X3-05 | K16: J25X19X3-05 | L16: 601.9 | M16: 19 | N16: 25 | O16: 1 | P16: 支 | R16: {=IFERROR(INDEX(板块数量!$B$2:$B$118,MATCH(0,IF((板块数量!$A$2:$A$118=$K$5)*(板块数量!$B$2:$B$118<>""),COUNTIF($R$8:R15,板块数量!$B$2:$B$118),1),0)),"")} | W16: =IF(OR(G16="型材",G16="尼龙"),H16,"-") -> 角铝 | X16: =IF(OR(G16="型材",G16="尼龙"),I16,"-") -> J25X19X3 | Y16: =IF(OR(G16="型材",G16="尼龙"),L16,"-") -> 601.9 | Z16: =IF(OR(G16="型材",G16="尼龙"),K16,"-") -> J25X19X3-05 | AA16: =IF(OR(G16="型材",G16="尼龙"),$N$6*O16,"-") -> 7 | AF16: =IF(OR(G16="型材",G16="尼龙"),H16,"-") -> 角铝 | AG16: =IF(OR(G16="型材",G16="尼龙"),I16,"-") -> J25X19X3 | AI16: =IF(OR(G16="型材",G16="尼龙"),L16,"-") -> 601.9 | AK16: =IF(OR(G16="型材",G16="尼龙"),$N$6*O16,"-") -> 7 | AP16: =IF($G16="配件",I16,"-") -> - | AQ16: =IF($G16="配件",H16,"-") -> - | AS16: =IF(OR(H16="泡沫条",H16="胶条"),$N$6*L16*O16/1000,IF(OR(H16="双面贴",H16="胶带"),L16*O16/1000,IF(AP16<>"-",$N$6*O16,"-"))) -> - | AT16: =IF(OR(H16="胶条",H16="泡沫条",H16="双面贴",H16="胶带"),"米",IF(AP16<>"-",P16,"-")) -> - | AY16: =IF($G16="玻璃",$H$7,"-") -> - | AZ16: =IF($G16="玻璃",J16,"-") -> - | BB16: =IF($G16="玻璃",M16,"-") -> - | BC16: =IF($G16="玻璃",L16,"-") -> - | BD16: =IF($G16="玻璃",$N$6*O16,"-") -> - | BE16: =BD16*BC16*BB16/1000000 -> #VALUE! | BF16: =IF($G16="玻璃",K16,"-") -> - | BI16: =IF($G16="铝板",$H$7,"-") -> - | BJ16: =IF($G16="铝板",J16,"-") -> - | BK16: =IF($G16="铝板",H16,"-") -> - | BL16: =IF($G16="铝板",M16,"-") -> - | BM16: =IF($G16="铝板",L16,"-") -> - | BN16: =IF($G16="铝板",$N$6*O16,"-") -> - | BO16: =BN16*BM16*BL16/1000000 -> #VALUE! | BP16: =IF($G16="铝板",K16,"-") -> - | BS16: =IF($G16="铁皮",$H$7,"-") -> - | BT16: =IF($G16="铁皮",J16,"-") -> - | BU16: =IF($G16="铁皮",H16,"-") -> - | BV16: =IF($G16="铁皮",M16,"-") -> - | BW16: =IF($G16="铁皮",L16,"-") -> - | BX16: =IF($G16="铁皮",$N$6*O16,"-") -> - | BY16: =BX16*BW16*BV16/1000000 -> #VALUE! | BZ16: =IF($G16="铁皮",K16,"-") -> - | CC16: =IF(G16="钢材",$H$7,"-") -> - | CD16: =IF(G16="钢材",J16,"-") -> - | CE16: =IF(G16="钢材",H16,"-") -> - | CF16: =IF(G16="钢材",L16,"-") -> - | CH16: =IF(G16="钢材",$N$6*O16,"-") -> - | CJ16: =IF(G16="钢材",K16,"-") -> - | CK16: =IF(G16="钢材",Q16,"-") -> -
B17: =IF(G17<>G16,B16+1,B16) -> 5 | C17: =IF(G17<>G16,1,C16+1) -> 4 | D17: =IF(G17="","",IFERROR(IF(AND(B17<>"",C17<>""),B17&"."&C17,""),"")) -> 5.4 | E17: 9 | F17: 8 | G17: 型材 | H17: 角铝 | I17: J25X19X3 | J17: J25X19X3-04 | K17: J25X19X3-04 | L17: 869 | M17: 19 | N17: 25 | O17: 1 | P17: 支 | R17: {=IFERROR(INDEX(板块数量!$B$2:$B$118,MATCH(0,IF((板块数量!$A$2:$A$118=$K$5)*(板块数量!$B$2:$B$118<>""),COUNTIF($R$8:R16,板块数量!$B$2:$B$118),1),0)),"")} | W17: =IF(OR(G17="型材",G17="尼龙"),H17,"-") -> 角铝 | X17: =IF(OR(G17="型材",G17="尼龙"),I17,"-") -> J25X19X3 | Y17: =IF(OR(G17="型材",G17="尼龙"),L17,"-") -> 869 | Z17: =IF(OR(G17="型材",G17="尼龙"),K17,"-") -> J25X19X3-04 | AA17: =IF(OR(G17="型材",G17="尼龙"),$N$6*O17,"-") -> 7 | AF17: =IF(OR(G17="型材",G17="尼龙"),H17,"-") -> 角铝 | AG17: =IF(OR(G17="型材",G17="尼龙"),I17,"-") -> J25X19X3 | AI17: =IF(OR(G17="型材",G17="尼龙"),L17,"-") -> 869 | AK17: =IF(OR(G17="型材",G17="尼龙"),$N$6*O17,"-") -> 7 | AP17: =IF($G17="配件",I17,"-") -> - | AQ17: =IF($G17="配件",H17,"-") -> - | AS17: =IF(OR(H17="泡沫条",H17="胶条"),$N$6*L17*O17/1000,IF(OR(H17="双面贴",H17="胶带"),L17*O17/1000,IF(AP17<>"-",$N$6*O17,"-"))) -> - | AT17: =IF(OR(H17="胶条",H17="泡沫条",H17="双面贴",H17="胶带"),"米",IF(AP17<>"-",P17,"-")) -> - | AY17: =IF($G17="玻璃",$H$7,"-") -> - | AZ17: =IF($G17="玻璃",J17,"-") -> - | BB17: =IF($G17="玻璃",M17,"-") -> - | BC17: =IF($G17="玻璃",L17,"-") -> - | BD17: =IF($G17="玻璃",$N$6*O17,"-") -> - | BE17: =BD17*BC17*BB17/1000000 -> #VALUE! | BF17: =IF($G17="玻璃",K17,"-") -> - | BI17: =IF($G17="铝板",$H$7,"-") -> - | BJ17: =IF($G17="铝板",J17,"-") -> - | BK17: =IF($G17="铝板",H17,"-") -> - | BL17: =IF($G17="铝板",M17,"-") -> - | BM17: =IF($G17="铝板",L17,"-") -> - | BN17: =IF($G17="铝板",$N$6*O17,"-") -> - | BO17: =BN17*BM17*BL17/1000000 -> #VALUE! | BP17: =IF($G17="铝板",K17,"-") -> - | BS17: =IF($G17="铁皮",$H$7,"-") -> - | BT17: =IF($G17="铁皮",J17,"-") -> - | BU17: =IF($G17="铁皮",H17,"-") -> - | BV17: =IF($G17="铁皮",M17,"-") -> - | BW17: =IF($G17="铁皮",L17,"-") -> - | BX17: =IF($G17="铁皮",$N$6*O17,"-") -> - | BY17: =BX17*BW17*BV17/1000000 -> #VALUE! | BZ17: =IF($G17="铁皮",K17,"-") -> - | CC17: =IF(G17="钢材",$H$7,"-") -> - | CD17: =IF(G17="钢材",J17,"-") -> - | CE17: =IF(G17="钢材",H17,"-") -> - | CF17: =IF(G17="钢材",L17,"-") -> - | CH17: =IF(G17="钢材",$N$6*O17,"-") -> - | CJ17: =IF(G17="钢材",K17,"-") -> - | CK17: =IF(G17="钢材",Q17,"-") -> -
B18: =IF(G18<>G17,B17+1,B17) -> 5 | C18: =IF(G18<>G17,1,C17+1) -> 5 | D18: =IF(G18="","",IFERROR(IF(AND(B18<>"",C18<>""),B18&"."&C18,""),"")) -> 5.5 | E18: 10 | F18: 9 | G18: 型材 | H18: 角铝 | I18: J25X19X3 | J18: J25X19X3-03 | K18: J25X19X3-03 | L18: 869 | M18: 19 | N18: 25 | O18: 1 | P18: 支 | R18: {=IFERROR(INDEX(板块数量!$B$2:$B$118,MATCH(0,IF((板块数量!$A$2:$A$118=$K$5)*(板块数量!$B$2:$B$118<>""),COUNTIF($R$8:R17,板块数量!$B$2:$B$118),1),0)),"")} | W18: =IF(OR(G18="型材",G18="尼龙"),H18,"-") -> 角铝 | X18: =IF(OR(G18="型材",G18="尼龙"),I18,"-") -> J25X19X3 | Y18: =IF(OR(G18="型材",G18="尼龙"),L18,"-") -> 869 | Z18: =IF(OR(G18="型材",G18="尼龙"),K18,"-") -> J25X19X3-03 | AA18: =IF(OR(G18="型材",G18="尼龙"),$N$6*O18,"-") -> 7 | AF18: =IF(OR(G18="型材",G18="尼龙"),H18,"-") -> 角铝 | AG18: =IF(OR(G18="型材",G18="尼龙"),I18,"-") -> J25X19X3 | AI18: =IF(OR(G18="型材",G18="尼龙"),L18,"-") -> 869 | AK18: =IF(OR(G18="型材",G18="尼龙"),$N$6*O18,"-") -> 7 | AP18: =IF($G18="配件",I18,"-") -> - | AQ18: =IF($G18="配件",H18,"-") -> - | AS18: =IF(OR(H18="泡沫条",H18="胶条"),$N$6*L18*O18/1000,IF(OR(H18="双面贴",H18="胶带"),L18*O18/1000,IF(AP18<>"-",$N$6*O18,"-"))) -> - | AT18: =IF(OR(H18="胶条",H18="泡沫条",H18="双面贴",H18="胶带"),"米",IF(AP18<>"-",P18,"-")) -> - | AY18: =IF($G18="玻璃",$H$7,"-") -> - | AZ18: =IF($G18="玻璃",J18,"-") -> - | BB18: =IF($G18="玻璃",M18,"-") -> - | BC18: =IF($G18="玻璃",L18,"-") -> - | BD18: =IF($G18="玻璃",$N$6*O18,"-") -> - | BE18: =BD18*BC18*BB18/1000000 -> #VALUE! | BF18: =IF($G18="玻璃",K18,"-") -> - | BI18: =IF($G18="铝板",$H$7,"-") -> - | BJ18: =IF($G18="铝板",J18,"-") -> - | BK18: =IF($G18="铝板",H18,"-") -> - | BL18: =IF($G18="铝板",M18,"-") -> - | BM18: =IF($G18="铝板",L18,"-") -> - | BN18: =IF($G18="铝板",$N$6*O18,"-") -> - | BO18: =BN18*BM18*BL18/1000000 -> #VALUE! | BP18: =IF($G18="铝板",K18,"-") -> - | BS18: =IF($G18="铁皮",$H$7,"-") -> - | BT18: =IF($G18="铁皮",J18,"-") -> - | BU18: =IF($G18="铁皮",H18,"-") -> - | BV18: =IF($G18="铁皮",M18,"-") -> - | BW18: =IF($G18="铁皮",L18,"-") -> - | BX18: =IF($G18="铁皮",$N$6*O18,"-") -> - | BY18: =BX18*BW18*BV18/1000000 -> #VALUE! | BZ18: =IF($G18="铁皮",K18,"-") -> - | CC18: =IF(G18="钢材",$H$7,"-") -> - | CD18: =IF(G18="钢材",J18,"-") -> - | CE18: =IF(G18="钢材",H18,"-") -> - | CF18: =IF(G18="钢材",L18,"-") -> - | CH18: =IF(G18="钢材",$N$6*O18,"-") -> - | CJ18: =IF(G18="钢材",K18,"-") -> - | CK18: =IF(G18="钢材",Q18,"-") -> -
B19: =IF(G19<>G18,B18+1,B18) -> 5 | C19: =IF(G19<>G18,1,C18+1) -> 6 | D19: =IF(G19="","",IFERROR(IF(AND(B19<>"",C19<>""),B19&"."&C19,""),"")) -> 5.6 | E19: 11 | F19: 10 | G19: 型材 | H19: 角铝 | I19: J25X19X3 | J19: J25X19X3-02 | K19: J25X19X3-02 | L19: 601.9 | M19: 19 | N19: 25 | O19: 1 | P19: 支 | R19: {=IFERROR(INDEX(板块数量!$B$2:$B$118,MATCH(0,IF((板块数量!$A$2:$A$118=$K$5)*(板块数量!$B$2:$B$118<>""),COUNTIF($R$8:R18,板块数量!$B$2:$B$118),1),0)),"")} | W19: =IF(OR(G19="型材",G19="尼龙"),H19,"-") -> 角铝 | X19: =IF(OR(G19="型材",G19="尼龙"),I19,"-") -> J25X19X3 | Y19: =IF(OR(G19="型材",G19="尼龙"),L19,"-") -> 601.9 | Z19: =IF(OR(G19="型材",G19="尼龙"),K19,"-") -> J25X19X3-02 | AA19: =IF(OR(G19="型材",G19="尼龙"),$N$6*O19,"-") -> 7 | AF19: =IF(OR(G19="型材",G19="尼龙"),H19,"-") -> 角铝 | AG19: =IF(OR(G19="型材",G19="尼龙"),I19,"-") -> J25X19X3 | AI19: =IF(OR(G19="型材",G19="尼龙"),L19,"-") -> 601.9 | AK19: =IF(OR(G19="型材",G19="尼龙"),$N$6*O19,"-") -> 7 | AP19: =IF($G19="配件",I19,"-") -> - | AQ19: =IF($G19="配件",H19,"-") -> - | AS19: =IF(OR(H19="泡沫条",H19="胶条"),$N$6*L19*O19/1000,IF(OR(H19="双面贴",H19="胶带"),L19*O19/1000,IF(AP19<>"-",$N$6*O19,"-"))) -> - | AT19: =IF(OR(H19="胶条",H19="泡沫条",H19="双面贴",H19="胶带"),"米",IF(AP19<>"-",P19,"-")) -> - | AY19: =IF($G19="玻璃",$H$7,"-") -> - | AZ19: =IF($G19="玻璃",J19,"-") -> - | BB19: =IF($G19="玻璃",M19,"-") -> - | BC19: =IF($G19="玻璃",L19,"-") -> - | BD19: =IF($G19="玻璃",$N$6*O19,"-") -> - | BE19: =BD19*BC19*BB19/1000000 -> #VALUE! | BF19: =IF($G19="玻璃",K19,"-") -> - | BI19: =IF($G19="铝板",$H$7,"-") -> - | BJ19: =IF($G19="铝板",J19,"-") -> - | BK19: =IF($G19="铝板",H19,"-") -> - | BL19: =IF($G19="铝板",M19,"-") -> - | BM19: =IF($G19="铝板",L19,"-") -> - | BN19: =IF($G19="铝板",$N$6*O19,"-") -> - | BO19: =BN19*BM19*BL19/1000000 -> #VALUE! | BP19: =IF($G19="铝板",K19,"-") -> - | BS19: =IF($G19="铁皮",$H$7,"-") -> - | BT19: =IF($G19="铁皮",J19,"-") -> - | BU19: =IF($G19="铁皮",H19,"-") -> - | BV19: =IF($G19="铁皮",M19,"-") -> - | BW19: =IF($G19="铁皮",L19,"-") -> - | BX19: =IF($G19="铁皮",$N$6*O19,"-") -> - | BY19: =BX19*BW19*BV19/1000000 -> #VALUE! | BZ19: =IF($G19="铁皮",K19,"-") -> - | CC19: =IF(G19="钢材",$H$7,"-") -> - | CD19: =IF(G19="钢材",J19,"-") -> - | CE19: =IF(G19="钢材",H19,"-") -> - | CF19: =IF(G19="钢材",L19,"-") -> - | CH19: =IF(G19="钢材",$N$6*O19,"-") -> - | CJ19: =IF(G19="钢材",K19,"-") -> - | CK19: =IF(G19="钢材",Q19,"-") -> -
B20: =IF(G20<>G19,B19+1,B19) -> 5 | C20: =IF(G20<>G19,1,C19+1) -> 7 | D20: =IF(G20="","",IFERROR(IF(AND(B20<>"",C20<>""),B20&"."&C20,""),"")) -> 5.7 | E20: 12 | F20: 11 | G20: 型材 | H20: 角铝 | I20: J25X19X3 | J20: J25X19X3-01 | K20: J25X19X3-01 | L20: 1298 | M20: 19 | N20: 25 | O20: 1 | P20: 支 | R20: {=IFERROR(INDEX(板块数量!$B$2:$B$118,MATCH(0,IF((板块数量!$A$2:$A$118=$K$5)*(板块数量!$B$2:$B$118<>""),COUNTIF($R$8:R19,板块数量!$B$2:$B$118),1),0)),"")} | W20: =IF(OR(G20="型材",G20="尼龙"),H20,"-") -> 角铝 | X20: =IF(OR(G20="型材",G20="尼龙"),I20,"-") -> J25X19X3 | Y20: =IF(OR(G20="型材",G20="尼龙"),L20,"-") -> 1298 | Z20: =IF(OR(G20="型材",G20="尼龙"),K20,"-") -> J25X19X3-01 | AA20: =IF(OR(G20="型材",G20="尼龙"),$N$6*O20,"-") -> 7 | AF20: =IF(OR(G20="型材",G20="尼龙"),H20,"-") -> 角铝 | AG20: =IF(OR(G20="型材",G20="尼龙"),I20,"-") -> J25X19X3 | AI20: =IF(OR(G20="型材",G20="尼龙"),L20,"-") -> 1298 | AK20: =IF(OR(G20="型材",G20="尼龙"),$N$6*O20,"-") -> 7 | AP20: =IF($G20="配件",I20,"-") -> - | AQ20: =IF($G20="配件",H20,"-") -> - | AS20: =IF(OR(H20="泡沫条",H20="胶条"),$N$6*L20*O20/1000,IF(OR(H20="双面贴",H20="胶带"),L20*O20/1000,IF(AP20<>"-",$N$6*O20,"-"))) -> - | AT20: =IF(OR(H20="胶条",H20="泡沫条",H20="双面贴",H20="胶带"),"米",IF(AP20<>"-",P20,"-")) -> - | AY20: =IF($G20="玻璃",$H$7,"-") -> - | AZ20: =IF($G20="玻璃",J20,"-") -> - | BB20: =IF($G20="玻璃",M20,"-") -> - | BC20: =IF($G20="玻璃",L20,"-") -> - | BD20: =IF($G20="玻璃",$N$6*O20,"-") -> - | BE20: =BD20*BC20*BB20/1000000 -> #VALUE! | BF20: =IF($G20="玻璃",K20,"-") -> - | BI20: =IF($G20="铝板",$H$7,"-") -> - | BJ20: =IF($G20="铝板",J20,"-") -> - | BK20: =IF($G20="铝板",H20,"-") -> - | BL20: =IF($G20="铝板",M20,"-") -> - | BM20: =IF($G20="铝板",L20,"-") -> - | BN20: =IF($G20="铝板",$N$6*O20,"-") -> - | BO20: =BN20*BM20*BL20/1000000 -> #VALUE! | BP20: =IF($G20="铝板",K20,"-") -> - | BS20: =IF($G20="铁皮",$H$7,"-") -> - | BT20: =IF($G20="铁皮",J20,"-") -> - | BU20: =IF($G20="铁皮",H20,"-") -> - | BV20: =IF($G20="铁皮",M20,"-") -> - | BW20: =IF($G20="铁皮",L20,"-") -> - | BX20: =IF($G20="铁皮",$N$6*O20,"-") -> - | BY20: =BX20*BW20*BV20/1000000 -> #VALUE! | BZ20: =IF($G20="铁皮",K20,"-") -> - | CC20: =IF(G20="钢材",$H$7,"-") -> - | CD20: =IF(G20="钢材",J20,"-") -> - | CE20: =IF(G20="钢材",H20,"-") -> - | CF20: =IF(G20="钢材",L20,"-") -> - | CH20: =IF(G20="钢材",$N$6*O20,"-") -> - | CJ20: =IF(G20="钢材",K20,"-") -> - | CK20: =IF(G20="钢材",Q20,"-") -> -
B21: =IF(G21<>G20,B20+1,B20) -> 5 | C21: =IF(G21<>G20,1,C20+1) -> 8 | D21: =IF(G21="","",IFERROR(IF(AND(B21<>"",C21<>""),B21&"."&C21,""),"")) -> 5.8 | E21: 13 | F21: 12 | G21: 型材 | H21: 竖向护边 | I21: DCC154H-511-LL | J21: CW154H-511-03 | K21: CW154H-511-03 | L21: 3760 | M21: 4.8 | N21: 15 | O21: 2 | P21: 支 | R21: {=IFERROR(INDEX(板块数量!$B$2:$B$118,MATCH(0,IF((板块数量!$A$2:$A$118=$K$5)*(板块数量!$B$2:$B$118<>""),COUNTIF($R$8:R20,板块数量!$B$2:$B$118),1),0)),"")} | W21: =IF(OR(G21="型材",G21="尼龙"),H21,"-") -> 竖向护边 | X21: =IF(OR(G21="型材",G21="尼龙"),I21,"-") -> DCC154H-511-LL | Y21: =IF(OR(G21="型材",G21="尼龙"),L21,"-") -> 3760 | Z21: =IF(OR(G21="型材",G21="尼龙"),K21,"-") -> CW154H-511-03 | AA21: =IF(OR(G21="型材",G21="尼龙"),$N$6*O21,"-") -> 14 | AF21: =IF(OR(G21="型材",G21="尼龙"),H21,"-") -> 竖向护边 | AG21: =IF(OR(G21="型材",G21="尼龙"),I21,"-") -> DCC154H-511-LL | AI21: =IF(OR(G21="型材",G21="尼龙"),L21,"-") -> 3760 | AK21: =IF(OR(G21="型材",G21="尼龙"),$N$6*O21,"-") -> 14 | AP21: =IF($G21="配件",I21,"-") -> - | AQ21: =IF($G21="配件",H21,"-") -> - | AS21: =IF(OR(H21="泡沫条",H21="胶条"),$N$6*L21*O21/1000,IF(OR(H21="双面贴",H21="胶带"),L21*O21/1000,IF(AP21<>"-",$N$6*O21,"-"))) -> - | AT21: =IF(OR(H21="胶条",H21="泡沫条",H21="双面贴",H21="胶带"),"米",IF(AP21<>"-",P21,"-")) -> - | AY21: =IF($G21="玻璃",$H$7,"-") -> - | AZ21: =IF($G21="玻璃",J21,"-") -> - | BB21: =IF($G21="玻璃",M21,"-") -> - | BC21: =IF($G21="玻璃",L21,"-") -> - | BD21: =IF($G21="玻璃",$N$6*O21,"-") -> - | BE21: =BD21*BC21*BB21/1000000 -> #VALUE! | BF21: =IF($G21="玻璃",K21,"-") -> - | BI21: =IF($G21="铝板",$H$7,"-") -> - | BJ21: =IF($G21="铝板",J21,"-") -> - | BK21: =IF($G21="铝板",H21,"-") -> - | BL21: =IF($G21="铝板",M21,"-") -> - | BM21: =IF($G21="铝板",L21,"-") -> - | BN21: =IF($G21="铝板",$N$6*O21,"-") -> - | BO21: =BN21*BM21*BL21/1000000 -> #VALUE! | BP21: =IF($G21="铝板",K21,"-") -> - | BS21: =IF($G21="铁皮",$H$7,"-") -> - | BT21: =IF($G21="铁皮",J21,"-") -> - | BU21: =IF($G21="铁皮",H21,"-") -> - | BV21: =IF($G21="铁皮",M21,"-") -> - | BW21: =IF($G21="铁皮",L21,"-") -> - | BX21: =IF($G21="铁皮",$N$6*O21,"-") -> - | BY21: =BX21*BW21*BV21/1000000 -> #VALUE! | BZ21: =IF($G21="铁皮",K21,"-") -> - | CC21: =IF(G21="钢材",$H$7,"-") -> - | CD21: =IF(G21="钢材",J21,"-") -> - | CE21: =IF(G21="钢材",H21,"-") -> - | CF21: =IF(G21="钢材",L21,"-") -> - | CH21: =IF(G21="钢材",$N$6*O21,"-") -> - | CJ21: =IF(G21="钢材",K21,"-") -> - | CK21: =IF(G21="钢材",Q21,"-") -> -
... B35: =IF(G35<>G34,B34+1,B34) -> 5 | C35: =IF(G35<>G34,1,C34+1) -> 22 | D35: =IF(G35="","",IFERROR(IF(AND(B35<>"",C35<>""),B35&"."&C35,""),"")) -> 5.22 | E35: 27 | F35: 26 | G35: 型材 | H35: 50x4垫片 | I35: B50X4 | J35: B50X4-01 | K35: B50X4-01 | L35: 250 | M35: 50 | N35: 4 | O35: 2 | P35: 支 | R35: {=IFERROR(INDEX(板块数量!$B$2:$B$118,MATCH(0,IF((板块数量!$A$2:$A$118=$K$5)*(板块数量!$B$2:$B$118<>""),COUNTIF($R$8:R34,板块数量!$B$2:$B$118),1),0)),"")} | W35: =IF(OR(G35="型材",G35="尼龙"),H35,"-") -> 50x4垫片 | X35: =IF(OR(G35="型材",G35="尼龙"),I35,"-") -> B50X4 | Y35: =IF(OR(G35="型材",G35="尼龙"),L35,"-") -> 250 | Z35: =IF(OR(G35="型材",G35="尼龙"),K35,"-") -> B50X4-01 | AA35: =IF(OR(G35="型材",G35="尼龙"),$N$6*O35,"-") -> 14 | AF35: =IF(OR(G35="型材",G35="尼龙"),H35,"-") -> 50x4垫片 | AG35: =IF(OR(G35="型材",G35="尼龙"),I35,"-") -> B50X4 | AI35: =IF(OR(G35="型材",G35="尼龙"),L35,"-") -> 250 | AK35: =IF(OR(G35="型材",G35="尼龙"),$N$6*O35,"-") -> 14 | AP35: =IF($G35="配件",I35,"-") -> - | AQ35: =IF($G35="配件",H35,"-") -> - | AS35: =IF(OR(H35="泡沫条",H35="胶条"),$N$6*L35*O35/1000,IF(OR(H35="双面贴",H35="胶带"),L35*O35/1000,IF(AP35<>"-",$N$6*O35,"-"))) -> - | AT35: =IF(OR(H35="胶条",H35="泡沫条",H35="双面贴",H35="胶带"),"米",IF(AP35<>"-",P35,"-")) -> - | AY35: =IF($G35="玻璃",$H$7,"-") -> - | AZ35: =IF($G35="玻璃",J35,"-") -> - | BB35: =IF($G35="玻璃",M35,"-") -> - | BC35: =IF($G35="玻璃",L35,"-") -> - | BD35: =IF($G35="玻璃",$N$6*O35,"-") -> - | BE35: =BD35*BC35*BB35/1000000 -> #VALUE! | BF35: =IF($G35="玻璃",K35,"-") -> - | BI35: =IF($G35="铝板",$H$7,"-") -> - | BJ35: =IF($G35="铝板",J35,"-") -> - | BK35: =IF($G35="铝板",H35,"-") -> - | BL35: =IF($G35="铝板",M35,"-") -> - | BM35: =IF($G35="铝板",L35,"-") -> - | BN35: =IF($G35="铝板",$N$6*O35,"-") -> - | BO35: =BN35*BM35*BL35/1000000 -> #VALUE! | BP35: =IF($G35="铝板",K35,"-") -> - | BS35: =IF($G35="铁皮",$H$7,"-") -> - | BT35: =IF($G35="铁皮",J35,"-") -> - | BU35: =IF($G35="铁皮",H35,"-") -> - | BV35: =IF($G35="铁皮",M35,"-") -> - | BW35: =IF($G35="铁皮",L35,"-") -> - | BX35: =IF($G35="铁皮",$N$6*O35,"-") -> - | BY35: =BX35*BW35*BV35/1000000 -> #VALUE! | BZ35: =IF($G35="铁皮",K35,"-") -> - | CC35: =IF(G35="钢材",$H$7,"-") -> - | CD35: =IF(G35="钢材",J35,"-") -> - | CE35: =IF(G35="钢材",H35,"-") -> - | CF35: =IF(G35="钢材",L35,"-") -> - | CH35: =IF(G35="钢材",$N$6*O35,"-") -> - | CJ35: =IF(G35="钢材",K35,"-") -> - | CK35: =IF(G35="钢材",Q35,"-") -> -
B36: =IF(G36<>G35,B35+1,B35) -> 6 | C36: =IF(G36<>G35,1,C35+1) -> 1 | D36: =IF(G36="","",IFERROR(IF(AND(B36<>"",C36<>""),B36&"."&C36,""),"")) | E36: 28 | F36: 27 | R36: {=IFERROR(INDEX(板块数量!$B$2:$B$118,MATCH(0,IF((板块数量!$A$2:$A$118=$K$5)*(板块数量!$B$2:$B$118<>""),COUNTIF($R$8:R35,板块数量!$B$2:$B$118),1),0)),"")} | W36: =IF(OR(G36="型材",G36="尼龙"),H36,"-") -> - | X36: =IF(OR(G36="型材",G36="尼龙"),I36,"-") -> - | Y36: =IF(OR(G36="型材",G36="尼龙"),L36,"-") -> - | Z36: =IF(OR(G36="型材",G36="尼龙"),K36,"-") -> - | AA36: =IF(OR(G36="型材",G36="尼龙"),$N$6*O36,"-") -> - | AF36: =IF(OR(G36="型材",G36="尼龙"),H36,"-") -> - | AG36: =IF(OR(G36="型材",G36="尼龙"),I36,"-") -> - | AI36: =IF(OR(G36="型材",G36="尼龙"),L36,"-") -> - | AK36: =IF(OR(G36="型材",G36="尼龙"),$N$6*O36,"-") -> - | AP36: =IF($G36="配件",I36,"-") -> - | AQ36: =IF($G36="配件",H36,"-") -> - | AS36: =IF(OR(H36="泡沫条",H36="胶条"),$N$6*L36*O36/1000,IF(OR(H36="双面贴",H36="胶带"),L36*O36/1000,IF(AP36<>"-",$N$6*O36,"-"))) -> - | AT36: =IF(OR(H36="胶条",H36="泡沫条",H36="双面贴",H36="胶带"),"米",IF(AP36<>"-",P36,"-")) -> - | AY36: =IF($G36="玻璃",$H$7,"-") -> - | AZ36: =IF($G36="玻璃",J36,"-") -> - | BB36: =IF($G36="玻璃",M36,"-") -> - | BC36: =IF($G36="玻璃",L36,"-") -> - | BD36: =IF($G36="玻璃",$N$6*O36,"-") -> - | BE36: =BD36*BC36*BB36/1000000 -> #VALUE! | BF36: =IF($G36="玻璃",K36,"-") -> - | BI36: =IF($G36="铝板",$H$7,"-") -> - | BJ36: =IF($G36="铝板",J36,"-") -> - | BK36: =IF($G36="铝板",H36,"-") -> - | BL36: =IF($G36="铝板",M36,"-") -> - | BM36: =IF($G36="铝板",L36,"-") -> - | BN36: =IF($G36="铝板",$N$6*O36,"-") -> - | BO36: =BN36*BM36*BL36/1000000 -> #VALUE! | BP36: =IF($G36="铝板",K36,"-") -> - | BS36: =IF($G36="铁皮",$H$7,"-") -> - | BT36: =IF($G36="铁皮",J36,"-") -> - | BU36: =IF($G36="铁皮",H36,"-") -> - | BV36: =IF($G36="铁皮",M36,"-") -> - | BW36: =IF($G36="铁皮",L36,"-") -> - | BX36: =IF($G36="铁皮",$N$6*O36,"-") -> - | BY36: =BX36*BW36*BV36/1000000 -> #VALUE! | BZ36: =IF($G36="铁皮",K36,"-") -> - | CC36: =IF(G36="钢材",$H$7,"-") -> - | CD36: =IF(G36="钢材",J36,"-") -> - | CE36: =IF(G36="钢材",H36,"-") -> - | CF36: =IF(G36="钢材",L36,"-") -> - | CH36: =IF(G36="钢材",$N$6*O36,"-") -> - | CJ36: =IF(G36="钢材",K36,"-") -> - | CK36: =IF(G36="钢材",Q36,"-") -> -
B37: =IF(G37<>G36,B36+1,B36) -> 6 | C37: =IF(G37<>G36,1,C36+1) -> 2 | D37: =IF(G37="","",IFERROR(IF(AND(B37<>"",C37<>""),B37&"."&C37,""),"")) | E37: 29 | F37: 28 | R37: {=IFERROR(INDEX(板块数量!$B$2:$B$118,MATCH(0,IF((板块数量!$A$2:$A$118=$K$5)*(板块数量!$B$2:$B$118<>""),COUNTIF($R$8:R36,板块数量!$B$2:$B$118),1),0)),"")} | W37: =IF(OR(G37="型材",G37="尼龙"),H37,"-") -> - | X37: =IF(OR(G37="型材",G37="尼龙"),I37,"-") -> - | Y37: =IF(OR(G37="型材",G37="尼龙"),L37,"-") -> - | Z37: =IF(OR(G37="型材",G37="尼龙"),K37,"-") -> - | AA37: =IF(OR(G37="型材",G37="尼龙"),$N$6*O37,"-") -> - | AF37: =IF(OR(G37="型材",G37="尼龙"),H37,"-") -> - | AG37: =IF(OR(G37="型材",G37="尼龙"),I37,"-") -> - | AI37: =IF(OR(G37="型材",G37="尼龙"),L37,"-") -> - | AK37: =IF(OR(G37="型材",G37="尼龙"),$N$6*O37,"-") -> - | AP37: =IF($G37="配件",I37,"-") -> - | AQ37: =IF($G37="配件",H37,"-") -> - | AS37: =IF(OR(H37="泡沫条",H37="胶条"),$N$6*L37*O37/1000,IF(OR(H37="双面贴",H37="胶带"),L37*O37/1000,IF(AP37<>"-",$N$6*O37,"-"))) -> - | AT37: =IF(OR(H37="胶条",H37="泡沫条",H37="双面贴",H37="胶带"),"米",IF(AP37<>"-",P37,"-")) -> - | AY37: =IF($G37="玻璃",$H$7,"-") -> - | AZ37: =IF($G37="玻璃",J37,"-") -> - | BB37: =IF($G37="玻璃",M37,"-") -> - | BC37: =IF($G37="玻璃",L37,"-") -> - | BD37: =IF($G37="玻璃",$N$6*O37,"-") -> - | BE37: =BD37*BC37*BB37/1000000 -> #VALUE! | BF37: =IF($G37="玻璃",K37,"-") -> - | BI37: =IF($G37="铝板",$H$7,"-") -> - | BJ37: =IF($G37="铝板",J37,"-") -> - | BK37: =IF($G37="铝板",H37,"-") -> - | BL37: =IF($G37="铝板",M37,"-") -> - | BM37: =IF($G37="铝板",L37,"-") -> - | BN37: =IF($G37="铝板",$N$6*O37,"-") -> - | BO37: =BN37*BM37*BL37/1000000 -> #VALUE! | BP37: =IF($G37="铝板",K37,"-") -> - | BS37: =IF($G37="铁皮",$H$7,"-") -> - | BT37: =IF($G37="铁皮",J37,"-") -> - | BU37: =IF($G37="铁皮",H37,"-") -> - | BV37: =IF($G37="铁皮",M37,"-") -> - | BW37: =IF($G37="铁皮",L37,"-") -> - | BX37: =IF($G37="铁皮",$N$6*O37,"-") -> - | BY37: =BX37*BW37*BV37/1000000 -> #VALUE! | BZ37: =IF($G37="铁皮",K37,"-") -> - | CC37: =IF(G37="钢材",$H$7,"-") -> - | CD37: =IF(G37="钢材",J37,"-") -> - | CE37: =IF(G37="钢材",H37,"-") -> - | CF37: =IF(G37="钢材",L37,"-") -> - | CH37: =IF(G37="钢材",$N$6*O37,"-") -> - | CJ37: =IF(G37="钢材",K37,"-") -> - | CK37: =IF(G37="钢材",Q37,"-") -> -
B38: =IF(G38<>G37,B37+1,B37) -> 6 | C38: =IF(G38<>G37,1,C37+1) -> 3 | D38: =IF(G38="","",IFERROR(IF(AND(B38<>"",C38<>""),B38&"."&C38,""),"")) | E38: 30 | F38: 29 | R38: {=IFERROR(INDEX(板块数量!$B$2:$B$118,MATCH(0,IF((板块数量!$A$2:$A$118=$K$5)*(板块数量!$B$2:$B$118<>""),COUNTIF($R$8:R37,板块数量!$B$2:$B$118),1),0)),"")} | W38: =IF(OR(G38="型材",G38="尼龙"),H38,"-") -> - | X38: =IF(OR(G38="型材",G38="尼龙"),I38,"-") -> - | Y38: =IF(OR(G38="型材",G38="尼龙"),L38,"-") -> - | Z38: =IF(OR(G38="型材",G38="尼龙"),K38,"-") -> - | AA38: =IF(OR(G38="型材",G38="尼龙"),$N$6*O38,"-") -> - | AF38: =IF(OR(G38="型材",G38="尼龙"),H38,"-") -> - | AG38: =IF(OR(G38="型材",G38="尼龙"),I38,"-") -> - | AI38: =IF(OR(G38="型材",G38="尼龙"),L38,"-") -> - | AK38: =IF(OR(G38="型材",G38="尼龙"),$N$6*O38,"-") -> - | AP38: =IF($G38="配件",I38,"-") -> - | AQ38: =IF($G38="配件",H38,"-") -> - | AS38: =IF(OR(H38="泡沫条",H38="胶条"),$N$6*L38*O38/1000,IF(OR(H38="双面贴",H38="胶带"),L38*O38/1000,IF(AP38<>"-",$N$6*O38,"-"))) -> - | AT38: =IF(OR(H38="胶条",H38="泡沫条",H38="双面贴",H38="胶带"),"米",IF(AP38<>"-",P38,"-")) -> - | AY38: =IF($G38="玻璃",$H$7,"-") -> - | AZ38: =IF($G38="玻璃",J38,"-") -> - | BB38: =IF($G38="玻璃",M38,"-") -> - | BC38: =IF($G38="玻璃",L38,"-") -> - | BD38: =IF($G38="玻璃",$N$6*O38,"-") -> - | BE38: =BD38*BC38*BB38/1000000 -> #VALUE! | BF38: =IF($G38="玻璃",K38,"-") -> - | BI38: =IF($G38="铝板",$H$7,"-") -> - | BJ38: =IF($G38="铝板",J38,"-") -> - | BK38: =IF($G38="铝板",H38,"-") -> - | BL38: =IF($G38="铝板",M38,"-") -> - | BM38: =IF($G38="铝板",L38,"-") -> - | BN38: =IF($G38="铝板",$N$6*O38,"-") -> - | BO38: =BN38*BM38*BL38/1000000 -> #VALUE! | BP38: =IF($G38="铝板",K38,"-") -> - | BS38: =IF($G38="铁皮",$H$7,"-") -> - | BT38: =IF($G38="铁皮",J38,"-") -> - | BU38: =IF($G38="铁皮",H38,"-") -> - | BV38: =IF($G38="铁皮",M38,"-") -> - | BW38: =IF($G38="铁皮",L38,"-") -> - | BX38: =IF($G38="铁皮",$N$6*O38,"-") -> - | BY38: =BX38*BW38*BV38/1000000 -> #VALUE! | BZ38: =IF($G38="铁皮",K38,"-") -> - | CC38: =IF(G38="钢材",$H$7,"-") -> - | CD38: =IF(G38="钢材",J38,"-") -> - | CE38: =IF(G38="钢材",H38,"-") -> - | CF38: =IF(G38="钢材",L38,"-") -> - | CH38: =IF(G38="钢材",$N$6*O38,"-") -> - | CJ38: =IF(G38="钢材",K38,"-") -> - | CK38: =IF(G38="钢材",Q38,"-") -> -
B39: =IF(G39<>G38,B38+1,B38) -> 6 | C39: =IF(G39<>G38,1,C38+1) -> 4 | D39: =IF(G39="","",IFERROR(IF(AND(B39<>"",C39<>""),B39&"."&C39,""),"")) | E39: 31 | F39: 30 | R39: {=IFERROR(INDEX(板块数量!$B$2:$B$118,MATCH(0,IF((板块数量!$A$2:$A$118=$K$5)*(板块数量!$B$2:$B$118<>""),COUNTIF($R$8:R38,板块数量!$B$2:$B$118),1),0)),"")} | W39: =IF(OR(G39="型材",G39="尼龙"),H39,"-") -> - | X39: =IF(OR(G39="型材",G39="尼龙"),I39,"-") -> - | Y39: =IF(OR(G39="型材",G39="尼龙"),L39,"-") -> - | Z39: =IF(OR(G39="型材",G39="尼龙"),K39,"-") -> - | AA39: =IF(OR(G39="型材",G39="尼龙"),$N$6*O39,"-") -> - | AF39: =IF(OR(G39="型材",G39="尼龙"),H39,"-") -> - | AG39: =IF(OR(G39="型材",G39="尼龙"),I39,"-") -> - | AI39: =IF(OR(G39="型材",G39="尼龙"),L39,"-") -> - | AK39: =IF(OR(G39="型材",G39="尼龙"),$N$6*O39,"-") -> - | AP39: =IF($G39="配件",I39,"-") -> - | AQ39: =IF($G39="配件",H39,"-") -> - | AS39: =IF(OR(H39="泡沫条",H39="胶条"),$N$6*L39*O39/1000,IF(OR(H39="双面贴",H39="胶带"),L39*O39/1000,IF(AP39<>"-",$N$6*O39,"-"))) -> - | AT39: =IF(OR(H39="胶条",H39="泡沫条",H39="双面贴",H39="胶带"),"米",IF(AP39<>"-",P39,"-")) -> - | AY39: =IF($G39="玻璃",$H$7,"-") -> - | AZ39: =IF($G39="玻璃",J39,"-") -> - | BB39: =IF($G39="玻璃",M39,"-") -> - | BC39: =IF($G39="玻璃",L39,"-") -> - | BD39: =IF($G39="玻璃",$N$6*O39,"-") -> - | BE39: =BD39*BC39*BB39/1000000 -> #VALUE! | BF39: =IF($G39="玻璃",K39,"-") -> - | BI39: =IF($G39="铝板",$H$7,"-") -> - | BJ39: =IF($G39="铝板",J39,"-") -> - | BK39: =IF($G39="铝板",H39,"-") -> - | BL39: =IF($G39="铝板",M39,"-") -> - | BM39: =IF($G39="铝板",L39,"-") -> - | BN39: =IF($G39="铝板",$N$6*O39,"-") -> - | BO39: =BN39*BM39*BL39/1000000 -> #VALUE! | BP39: =IF($G39="铝板",K39,"-") -> - | BS39: =IF($G39="铁皮",$H$7,"-") -> - | BT39: =IF($G39="铁皮",J39,"-") -> - | BU39: =IF($G39="铁皮",H39,"-") -> - | BV39: =IF($G39="铁皮",M39,"-") -> - | BW39: =IF($G39="铁皮",L39,"-") -> - | BX39: =IF($G39="铁皮",$N$6*O39,"-") -> - | BY39: =BX39*BW39*BV39/1000000 -> #VALUE! | BZ39: =IF($G39="铁皮",K39,"-") -> - | CC39: =IF(G39="钢材",$H$7,"-") -> - | CD39: =IF(G39="钢材",J39,"-") -> - | CE39: =IF(G39="钢材",H39,"-") -> - | CF39: =IF(G39="钢材",L39,"-") -> - | CH39: =IF(G39="钢材",$N$6*O39,"-") -> - | CJ39: =IF(G39="钢材",K39,"-") -> - | CK39: =IF(G39="钢材",Q39,"-") -> -
B40: =IF(G40<>G39,B39+1,B39) -> 6 | C40: =IF(G40<>G39,1,C39+1) -> 5 | D40: =IF(G40="","",IFERROR(IF(AND(B40<>"",C40<>""),B40&"."&C40,""),"")) | E40: 32 | F40: 31 | R40: {=IFERROR(INDEX(板块数量!$B$2:$B$118,MATCH(0,IF((板块数量!$A$2:$A$118=$K$5)*(板块数量!$B$2:$B$118<>""),COUNTIF($R$8:R39,板块数量!$B$2:$B$118),1),0)),"")} | W40: =IF(OR(G40="型材",G40="尼龙"),H40,"-") -> - | X40: =IF(OR(G40="型材",G40="尼龙"),I40,"-") -> - | Y40: =IF(OR(G40="型材",G40="尼龙"),L40,"-") -> - | Z40: =IF(OR(G40="型材",G40="尼龙"),K40,"-") -> - | AA40: =IF(OR(G40="型材",G40="尼龙"),$N$6*O40,"-") -> - | AF40: =IF(OR(G40="型材",G40="尼龙"),H40,"-") -> - | AG40: =IF(OR(G40="型材",G40="尼龙"),I40,"-") -> - | AI40: =IF(OR(G40="型材",G40="尼龙"),L40,"-") -> - | AK40: =IF(OR(G40="型材",G40="尼龙"),$N$6*O40,"-") -> - | AP40: =IF($G40="配件",I40,"-") -> - | AQ40: =IF($G40="配件",H40,"-") -> - | AS40: =IF(OR(H40="泡沫条",H40="胶条"),$N$6*L40*O40/1000,IF(OR(H40="双面贴",H40="胶带"),L40*O40/1000,IF(AP40<>"-",$N$6*O40,"-"))) -> - | AT40: =IF(OR(H40="胶条",H40="泡沫条",H40="双面贴",H40="胶带"),"米",IF(AP40<>"-",P40,"-")) -> - | AY40: =IF($G40="玻璃",$H$7,"-") -> - | AZ40: =IF($G40="玻璃",J40,"-") -> - | BB40: =IF($G40="玻璃",M40,"-") -> - | BC40: =IF($G40="玻璃",L40,"-") -> - | BD40: =IF($G40="玻璃",$N$6*O40,"-") -> - | BE40: =BD40*BC40*BB40/1000000 -> #VALUE! | BF40: =IF($G40="玻璃",K40,"-") -> - | BI40: =IF($G40="铝板",$H$7,"-") -> - | BJ40: =IF($G40="铝板",J40,"-") -> - | BK40: =IF($G40="铝板",H40,"-") -> - | BL40: =IF($G40="铝板",M40,"-") -> - | BM40: =IF($G40="铝板",L40,"-") -> - | BN40: =IF($G40="铝板",$N$6*O40,"-") -> - | BO40: =BN40*BM40*BL40/1000000 -> #VALUE! | BP40: =IF($G40="铝板",K40,"-") -> - | BS40: =IF($G40="铁皮",$H$7,"-") -> - | BT40: =IF($G40="铁皮",J40,"-") -> - | BU40: =IF($G40="铁皮",H40,"-") -> - | BV40: =IF($G40="铁皮",M40,"-") -> - | BW40: =IF($G40="铁皮",L40,"-") -> - | BX40: =IF($G40="铁皮",$N$6*O40,"-") -> - | BY40: =BX40*BW40*BV40/1000000 -> #VALUE! | BZ40: =IF($G40="铁皮",K40,"-") -> - | CC40: =IF(G40="钢材",$H$7,"-") -> - | CD40: =IF(G40="钢材",J40,"-") -> - | CE40: =IF(G40="钢材",H40,"-") -> - | CF40: =IF(G40="钢材",L40,"-") -> - | CH40: =IF(G40="钢材",$N$6*O40,"-") -> - | CJ40: =IF(G40="钢材",K40,"-") -> - | CK40: =IF(G40="钢材",Q40,"-") -> -
B41: =IF(G41<>G40,B40+1,B40) -> 6 | C41: =IF(G41<>G40,1,C40+1) -> 6 | D41: =IF(G41="","",IFERROR(IF(AND(B41<>"",C41<>""),B41&"."&C41,""),"")) | E41: 33 | F41: 32 | R41: {=IFERROR(INDEX(板块数量!$B$2:$B$118,MATCH(0,IF((板块数量!$A$2:$A$118=$K$5)*(板块数量!$B$2:$B$118<>""),COUNTIF($R$8:R40,板块数量!$B$2:$B$118),1),0)),"")} | W41: =IF(OR(G41="型材",G41="尼龙"),H41,"-") -> - | X41: =IF(OR(G41="型材",G41="尼龙"),I41,"-") -> - | Y41: =IF(OR(G41="型材",G41="尼龙"),L41,"-") -> - | Z41: =IF(OR(G41="型材",G41="尼龙"),K41,"-") -> - | AA41: =IF(OR(G41="型材",G41="尼龙"),$N$6*O41,"-") -> - | AF41: =IF(OR(G41="型材",G41="尼龙"),H41,"-") -> - | AG41: =IF(OR(G41="型材",G41="尼龙"),I41,"-") -> - | AI41: =IF(OR(G41="型材",G41="尼龙"),L41,"-") -> - | AK41: =IF(OR(G41="型材",G41="尼龙"),$N$6*O41,"-") -> - | AP41: =IF($G41="配件",I41,"-") -> - | AQ41: =IF($G41="配件",H41,"-") -> - | AS41: =IF(OR(H41="泡沫条",H41="胶条"),$N$6*L41*O41/1000,IF(OR(H41="双面贴",H41="胶带"),L41*O41/1000,IF(AP41<>"-",$N$6*O41,"-"))) -> - | AT41: =IF(OR(H41="胶条",H41="泡沫条",H41="双面贴",H41="胶带"),"米",IF(AP41<>"-",P41,"-")) -> - | AY41: =IF($G41="玻璃",$H$7,"-") -> - | AZ41: =IF($G41="玻璃",J41,"-") -> - | BB41: =IF($G41="玻璃",M41,"-") -> - | BC41: =IF($G41="玻璃",L41,"-") -> - | BD41: =IF($G41="玻璃",$N$6*O41,"-") -> - | BE41: =BD41*BC41*BB41/1000000 -> #VALUE! | BF41: =IF($G41="玻璃",K41,"-") -> - | BI41: =IF($G41="铝板",$H$7,"-") -> - | BJ41: =IF($G41="铝板",J41,"-") -> - | BK41: =IF($G41="铝板",H41,"-") -> - | BL41: =IF($G41="铝板",M41,"-") -> - | BM41: =IF($G41="铝板",L41,"-") -> - | BN41: =IF($G41="铝板",$N$6*O41,"-") -> - | BO41: =BN41*BM41*BL41/1000000 -> #VALUE! | BP41: =IF($G41="铝板",K41,"-") -> - | BS41: =IF($G41="铁皮",$H$7,"-") -> - | BT41: =IF($G41="铁皮",J41,"-") -> - | BU41: =IF($G41="铁皮",H41,"-") -> - | BV41: =IF($G41="铁皮",M41,"-") -> - | BW41: =IF($G41="铁皮",L41,"-") -> - | BX41: =IF($G41="铁皮",$N$6*O41,"-") -> - | BY41: =BX41*BW41*BV41/1000000 -> #VALUE! | BZ41: =IF($G41="铁皮",K41,"-") -> - | CC41: =IF(G41="钢材",$H$7,"-") -> - | CD41: =IF(G41="钢材",J41,"-") -> - | CE41: =IF(G41="钢材",H41,"-") -> - | CF41: =IF(G41="钢材",L41,"-") -> - | CH41: =IF(G41="钢材",$N$6*O41,"-") -> - | CJ41: =IF(G41="钢材",K41,"-") -> - | CK41: =IF(G41="钢材",Q41,"-") -> -
B42: =IF(G42<>G41,B41+1,B41) -> 6 | C42: =IF(G42<>G41,1,C41+1) -> 7 | D42: =IF(G42="","",IFERROR(IF(AND(B42<>"",C42<>""),B42&"."&C42,""),"")) | E42: 34 | F42: 33 | R42: {=IFERROR(INDEX(板块数量!$B$2:$B$118,MATCH(0,IF((板块数量!$A$2:$A$118=$K$5)*(板块数量!$B$2:$B$118<>""),COUNTIF($R$8:R41,板块数量!$B$2:$B$118),1),0)),"")} | W42: =IF(OR(G42="型材",G42="尼龙"),H42,"-") -> - | X42: =IF(OR(G42="型材",G42="尼龙"),I42,"-") -> - | Y42: =IF(OR(G42="型材",G42="尼龙"),L42,"-") -> - | Z42: =IF(OR(G42="型材",G42="尼龙"),K42,"-") -> - | AA42: =IF(OR(G42="型材",G42="尼龙"),$N$6*O42,"-") -> - | AF42: =IF(OR(G42="型材",G42="尼龙"),H42,"-") -> - | AG42: =IF(OR(G42="型材",G42="尼龙"),I42,"-") -> - | AI42: =IF(OR(G42="型材",G42="尼龙"),L42,"-") -> - | AK42: =IF(OR(G42="型材",G42="尼龙"),$N$6*O42,"-") -> - | AP42: =IF($G42="配件",I42,"-") -> - | AQ42: =IF($G42="配件",H42,"-") -> - | AS42: =IF(OR(H42="泡沫条",H42="胶条"),$N$6*L42*O42/1000,IF(OR(H42="双面贴",H42="胶带"),L42*O42/1000,IF(AP42<>"-",$N$6*O42,"-"))) -> - | AT42: =IF(OR(H42="胶条",H42="泡沫条",H42="双面贴",H42="胶带"),"米",IF(AP42<>"-",P42,"-")) -> - | AY42: =IF($G42="玻璃",$H$7,"-") -> - | AZ42: =IF($G42="玻璃",J42,"-") -> - | BB42: =IF($G42="玻璃",M42,"-") -> - | BC42: =IF($G42="玻璃",L42,"-") -> - | BD42: =IF($G42="玻璃",$N$6*O42,"-") -> - | BE42: =BD42*BC42*BB42/1000000 -> #VALUE! | BF42: =IF($G42="玻璃",K42,"-") -> - | BI42: =IF($G42="铝板",$H$7,"-") -> - | BJ42: =IF($G42="铝板",J42,"-") -> - | BK42: =IF($G42="铝板",H42,"-") -> - | BL42: =IF($G42="铝板",M42,"-") -> - | BM42: =IF($G42="铝板",L42,"-") -> - | BN42: =IF($G42="铝板",$N$6*O42,"-") -> - | BO42: =BN42*BM42*BL42/1000000 -> #VALUE! | BP42: =IF($G42="铝板",K42,"-") -> - | BS42: =IF($G42="铁皮",$H$7,"-") -> - | BT42: =IF($G42="铁皮",J42,"-") -> - | BU42: =IF($G42="铁皮",H42,"-") -> - | BV42: =IF($G42="铁皮",M42,"-") -> - | BW42: =IF($G42="铁皮",L42,"-") -> - | BX42: =IF($G42="铁皮",$N$6*O42,"-") -> - | BY42: =BX42*BW42*BV42/1000000 -> #VALUE! | BZ42: =IF($G42="铁皮",K42,"-") -> - | CC42: =IF(G42="钢材",$H$7,"-") -> - | CD42: =IF(G42="钢材",J42,"-") -> - | CE42: =IF(G42="钢材",H42,"-") -> - | CF42: =IF(G42="钢材",L42,"-") -> - | CH42: =IF(G42="钢材",$N$6*O42,"-") -> - | CJ42: =IF(G42="钢材",K42,"-") -> - | CK42: =IF(G42="钢材",Q42,"-") -> -
B43: =IF(G43<>G42,B42+1,B42) -> 6 | C43: =IF(G43<>G42,1,C42+1) -> 8 | D43: =IF(G43="","",IFERROR(IF(AND(B43<>"",C43<>""),B43&"."&C43,""),"")) | E43: 35 | F43: 34 | R43: {=IFERROR(INDEX(板块数量!$B$2:$B$118,MATCH(0,IF((板块数量!$A$2:$A$118=$K$5)*(板块数量!$B$2:$B$118<>""),COUNTIF($R$8:R42,板块数量!$B$2:$B$118),1),0)),"")} | W43: =IF(OR(G43="型材",G43="尼龙"),H43,"-") -> - | X43: =IF(OR(G43="型材",G43="尼龙"),I43,"-") -> - | Y43: =IF(OR(G43="型材",G43="尼龙"),L43,"-") -> - | Z43: =IF(OR(G43="型材",G43="尼龙"),K43,"-") -> - | AA43: =IF(OR(G43="型材",G43="尼龙"),$N$6*O43,"-") -> - | AF43: =IF(OR(G43="型材",G43="尼龙"),H43,"-") -> - | AG43: =IF(OR(G43="型材",G43="尼龙"),I43,"-") -> - | AI43: =IF(OR(G43="型材",G43="尼龙"),L43,"-") -> - | AK43: =IF(OR(G43="型材",G43="尼龙"),$N$6*O43,"-") -> - | AP43: =IF($G43="配件",I43,"-") -> - | AQ43: =IF($G43="配件",H43,"-") -> - | AS43: =IF(OR(H43="泡沫条",H43="胶条"),$N$6*L43*O43/1000,IF(OR(H43="双面贴",H43="胶带"),L43*O43/1000,IF(AP43<>"-",$N$6*O43,"-"))) -> - | AT43: =IF(OR(H43="胶条",H43="泡沫条",H43="双面贴",H43="胶带"),"米",IF(AP43<>"-",P43,"-")) -> - | AY43: =IF($G43="玻璃",$H$7,"-") -> - | AZ43: =IF($G43="玻璃",J43,"-") -> - | BB43: =IF($G43="玻璃",M43,"-") -> - | BC43: =IF($G43="玻璃",L43,"-") -> - | BD43: =IF($G43="玻璃",$N$6*O43,"-") -> - | BE43: =BD43*BC43*BB43/1000000 -> #VALUE! | BF43: =IF($G43="玻璃",K43,"-") -> - | BI43: =IF($G43="铝板",$H$7,"-") -> - | BJ43: =IF($G43="铝板",J43,"-") -> - | BK43: =IF($G43="铝板",H43,"-") -> - | BL43: =IF($G43="铝板",M43,"-") -> - | BM43: =IF($G43="铝板",L43,"-") -> - | BN43: =IF($G43="铝板",$N$6*O43,"-") -> - | BO43: =BN43*BM43*BL43/1000000 -> #VALUE! | BP43: =IF($G43="铝板",K43,"-") -> - | BS43: =IF($G43="铁皮",$H$7,"-") -> - | BT43: =IF($G43="铁皮",J43,"-") -> - | BU43: =IF($G43="铁皮",H43,"-") -> - | BV43: =IF($G43="铁皮",M43,"-") -> - | BW43: =IF($G43="铁皮",L43,"-") -> - | BX43: =IF($G43="铁皮",$N$6*O43,"-") -> - | BY43: =BX43*BW43*BV43/1000000 -> #VALUE! | BZ43: =IF($G43="铁皮",K43,"-") -> - | CC43: =IF(G43="钢材",$H$7,"-") -> - | CD43: =IF(G43="钢材",J43,"-") -> - | CE43: =IF(G43="钢材",H43,"-") -> - | CF43: =IF(G43="钢材",L43,"-") -> - | CH43: =IF(G43="钢材",$N$6*O43,"-") -> - | CJ43: =IF(G43="钢材",K43,"-") -> - | CK43: =IF(G43="钢材",Q43,"-") -> -
